Workbook

Sheet Pitcher
A1: Player | B1: BABIP | C1: BABIP_3yr | D1: BABIP_Delta | E1: BABIP_Expectation_Category
A2: Taylor Clarke | B2: =VLOOKUP(A2,BABIP!$B$1:$W$476,12,FALSE) -> 0.208 | C2: =VLOOKUP(A2,BABIP_3yr!$B$1:$W$577,12,FALSE) -> 0.291 | D2: =B2-C2 -> -0.083 | E2: Regress
A3: Chris Flexen | B3: =VLOOKUP(A3,BABIP!$B$1:$W$476,12,FALSE) -> 0.226 | C3: =VLOOKUP(A3,BABIP_3yr!$B$1:$W$577,12,FALSE) -> 0.308 | D3: =B3-C3 -> -0.082 | E3: Regress
A4: DL Hall | B4: =VLOOKUP(A4,BABIP!$B$1:$W$476,12,FALSE) -> 0.202 | C4: =VLOOKUP(A4,BABIP_3yr!$B$1:$W$577,12,FALSE) -> 0.284 | D4: =B4-C4 -> -0.082 | E4: Regress
A5: Chris Murphy | B5: =VLOOKUP(A5,BABIP!$B$1:$W$476,12,FALSE) -> 0.191 | C5: =VLOOKUP(A5,BABIP_3yr!$B$1:$W$577,12,FALSE) -> 0.271 | D5: =B5-C5 -> -0.08 | E5: Regress
A6: Shawn Armstrong | B6: =VLOOKUP(A6,BABIP!$B$1:$W$476,12,FALSE) -> 0.196 | C6: =VLOOKUP(A6,BABIP_3yr!$B$1:$W$577,12,FALSE) -> 0.274 | D6: =B6-C6 -> -0.078 | E6: Regress
A7: Aroldis Chapman | B7: =VLOOKUP(A7,BABIP!$B$1:$W$476,12,FALSE) -> 0.2 | C7: =VLOOKUP(A7,BABIP_3yr!$B$1:$W$577,12,FALSE) -> 0.276 | D7: =B7-C7 -> -0.076 | E7: Regress
A8: Martín Pérez | B8: =VLOOKUP(A8,BABIP!$B$1:$W$476,12,FALSE) -> 0.221 | C8: =VLOOKUP(A8,BABIP_3yr!$B$1:$W$577,12,FALSE) -> 0.291 | D8: =B8-C8 -> -0.07 | E8: Regress
A9: Dylan Dodd | B9: =VLOOKUP(A9,BABIP!$B$1:$W$476,12,FALSE) -> 0.242 | C9: =VLOOKUP(A9,BABIP_3yr!$B$1:$W$577,12,FALSE) -> 0.311 | D9: =B9-C9 -> -0.069 | E9: Regress
A10: Nick Mears | B10: =VLOOKUP(A10,BABIP!$B$1:$W$476,12,FALSE) -> 0.227 | C10: =VLOOKUP(A10,BABIP_3yr!$B$1:$W$577,12,FALSE) -> 0.288 | D10: =B10-C10 -> -0.061 | E10: Regress
A11: Jalen Beeks | B11: =VLOOKUP(A11,BABIP!$B$1:$W$476,12,FALSE) -> 0.231 | C11: =VLOOKUP(A11,BABIP_3yr!$B$1:$W$577,12,FALSE) -> 0.292 | D11: =B11-C11 -> -0.061 | E11: Regress
A12: Johan Oviedo | B12: =VLOOKUP(A12,BABIP!$B$1:$W$476,12,FALSE) -> 0.208 | C12: =VLOOKUP(A12,BABIP_3yr!$B$1:$W$577,12,FALSE) -> 0.268 | D12: =B12-C12 -> -0.06 | E12: Regress
A13: Ian Hamilton | B13: =VLOOKUP(A13,BABIP!$B$1:$W$476,12,FALSE) -> 0.24 | C13: =VLOOKUP(A13,BABIP_3yr!$B$1:$W$577,12,FALSE) -> 0.299 | D13: =B13-C13 -> -0.059 | E13: Regress
... A398: Kirby Yates | B398: =VLOOKUP(A398,BABIP!$B$1:$W$476,12,FALSE) -> 0.293 | C398: =VLOOKUP(A398,BABIP_3yr!$B$1:$W$577,12,FALSE) -> 0.22 | D398: =B398-C398 -> 0.073 | E398: Improve
A399: AJ Blubaugh | B399: =VLOOKUP(A399,BABIP!$B$1:$W$476,12,FALSE) -> 0.153 | C399: =VLOOKUP(A399,BABIP_3yr!$B$1:$W$577,12,FALSE) -> #N/A | D399: =B399-C399 -> #N/A
A400: Cole Winn | B400: =VLOOKUP(A400,BABIP!$B$1:$W$476,12,FALSE) -> 0.194 | C400: =VLOOKUP(A400,BABIP_3yr!$B$1:$W$577,12,FALSE) -> #N/A | D400: =B400-C400 -> #N/A
A401: Troy Melton | B401: =VLOOKUP(A401,BABIP!$B$1:$W$476,12,FALSE) -> 0.198 | C401: =VLOOKUP(A401,BABIP_3yr!$B$1:$W$577,12,FALSE) -> #N/A | D401: =B401-C401 -> #N/A
A402: José Fermin | B402: =VLOOKUP(A402,BABIP!$B$1:$W$476,12,FALSE) -> 0.21 | C402: =VLOOKUP(A402,BABIP_3yr!$B$1:$W$577,12,FALSE) -> #N/A | D402: =B402-C402 -> #N/A
A403: Chase Shugart | B403: =VLOOKUP(A403,BABIP!$B$1:$W$476,12,FALSE) -> 0.214 | C403: =VLOOKUP(A403,BABIP_3yr!$B$1:$W$577,12,FALSE) -> #N/A | D403: =B403-C403 -> #N/A
A404: Matt Svanson | B404: =VLOOKUP(A404,BABIP!$B$1:$W$476,12,FALSE) -> 0.216 | C404: =VLOOKUP(A404,BABIP_3yr!$B$1:$W$577,12,FALSE) -> #N/A | D404: =B404-C404 -> #N/A
A405: John Curtiss | B405: =VLOOKUP(A405,BABIP!$B$1:$W$476,12,FALSE) -> 0.224 | C405: =VLOOKUP(A405,BABIP_3yr!$B$1:$W$577,12,FALSE) -> #N/A | D405: =B405-C405 -> #N/A
A406: Jack Perkins | B406: =VLOOKUP(A406,BABIP!$B$1:$W$476,12,FALSE) -> 0.23 | C406: =VLOOKUP(A406,BABIP_3yr!$B$1:$W$577,12,FALSE) -> #N/A | D406: =B406-C406 -> #N/A
A407: Luis Morales | B407: =VLOOKUP(A407,BABIP!$B$1:$W$476,12,FALSE) -> 0.233 | C407: =VLOOKUP(A407,BABIP_3yr!$B$1:$W$577,12,FALSE) -> #N/A | D407: =B407-C407 -> #N/A
A408: Justin Sterner | B408: =VLOOKUP(A408,BABIP!$B$1:$W$476,12,FALSE) -> 0.234 | C408: =VLOOKUP(A408,BABIP_3yr!$B$1:$W$577,12,FALSE) -> #N/A | D408: =B408-C408 -> #N/A
A409: Roki Sasaki | B409: =VLOOKUP(A409,BABIP!$B$1:$W$476,12,FALSE) -> 0.235 | C409: =VLOOKUP(A409,BABIP_3yr!$B$1:$W$577,12,FALSE) -> #N/A | D409: =B409-C409 -> #N/A
A410: Mason Fluharty | B410: =VLOOKUP(A410,BABIP!$B$1:$W$476,12,FALSE) -> 0.236 | C410: =VLOOKUP(A410,BABIP_3yr!$B$1:$W$577,12,FALSE) -> #N/A | D410: =B410-C410 -> #N/A
... A476: Grant Taylor | B476: =VLOOKUP(A476,BABIP!$B$1:$W$476,12,FALSE) -> 0.42 | C476: =VLOOKUP(A476,BABIP_3yr!$B$1:$W$577,12,FALSE) -> #N/A | D476: =B476-C476 -> #N/A

Sheet BABIP
A1: # | B1: Name | C1: Team | D1: W | E1: L | F1: SV | G1: G | H1: GS | I1: IP | J1: K/9 | K1: BB/9 | L1: HR/9 | M1: BABIP | N1: LOB% | O1: GB% | P1: HR/FB | Q1: vFA (pi) | R1: ERA | S1: xERA | T1: FIP | U1: xFIP | V1: WAR
A2: 1 | B2: AJ Blubaugh | C2: HOU | D2: 3 | E2: 1 | F2: 0 | G2: 11 | H2: 3 | I2: 32 | J2: 9.84 | K2: 3.09 | L2: 1.69 | M2: 0.153 | N2: 0.867 | O2: 0.338 | P2: 0.136 | Q2: 94.5 | R2: 1.69 | S2: 3.2 | T2: 4.42 | U2: 4.1 | V2: 0.1
A3: 2 | B3: Chris Murphy | C3: BOS | D3: 3 | E3: 0 | F3: 0 | G3: 23 | H3: 0 | I3: 34.2 | J3: 7.79 | K3: 5.19 | L3: 1.04 | M3: 0.191 | N3: 0.842 | O3: 0.543 | P3: 0.138 | Q3: 94.3 | R3: 3.12 | S3: 4 | T3: 5.07 | U3: 4.86 | V3: -0.2
A4: 3 | B4: Cole Winn | C4: TEX | D4: 0 | E4: 1 | F4: 0 | G4: 33 | H4: 0 | I4: 41.2 | J4: 7.56 | K4: 3.67 | L4: 0.65 | M4: 0.194 | N4: 0.905 | O4: 0.471 | P4: 0.079 | Q4: 96.3 | R4: 1.51 | S4: 4.19 | T4: 3.9 | U4: 4.37 | V4: 0.2
A5: 4 | B5: Kenley Jansen | C5: LAA | D5: 5 | E5: 4 | F5: 29 | G5: 62 | H5: 0 | I5: 59 | J5: 8.69 | K5: 2.9 | L5: 1.22 | M5: 0.195 | N5: 0.852 | O5: 0.273 | P5: 0.088 | R5: 2.59 | S5: 3.73 | T5: 3.98 | U5: 4.6 | V5: 0.6
A6: 5 | B6: Shawn Armstrong | C6: TEX | D6: 4 | E6: 3 | F6: 9 | G6: 71 | H6: 2 | I6: 74 | J6: 9 | K6: 2.43 | L6: 0.61 | M6: 0.196 | N6: 0.763 | O6: 0.359 | P6: 0.058 | Q6: 93.6 | R6: 2.31 | S6: 3.02 | T6: 3.07 | U6: 3.98 | V6: 1.4
A7: 6 | B7: Félix Bautista | C7: BAL | D7: 1 | E7: 1 | F7: 19 | G7: 35 | H7: 0 | I7: 34.2 | J7: 12.98 | K7: 5.97 | L7: 0.78 | M7: 0.197 | N7: 0.833 | O7: 0.507 | P7: 0.12 | R7: 2.6 | S7: 2.83 | T7: 3.37 | U7: 3.35 | V7: 0.6
A8: 7 | B8: Troy Melton | C8: DET | D8: 3 | E8: 2 | F8: 0 | G8: 16 | H8: 4 | I8: 45.2 | J8: 7.09 | K8: 2.96 | L8: 1.38 | M8: 0.198 | N8: 0.86 | O8: 0.425 | P8: 0.123 | Q8: 97.1 | R8: 2.76 | S8: 3.64 | T8: 4.6 | U8: 4.53 | V8: 0.1
A9: 8 | B9: Aroldis Chapman | C9: BOS | D9: 5 | E9: 3 | F9: 32 | G9: 67 | H9: 0 | I9: 61.1 | J9: 12.47 | K9: 2.2 | L9: 0.44 | M9: 0.2 | N9: 0.876 | O9: 0.386 | P9: 0.053 | Q9: 98.5 | R9: 1.17 | S9: 2.06 | T9: 1.73 | U9: 2.53 | V9: 2.6
A10: 9 | B10: Emilio Pagán | C10: CIN | D10: 2 | E10: 4 | F10: 32 | G10: 70 | H10: 0 | I10: 68.2 | J10: 10.62 | K10: 2.88 | L10: 1.31 | M10: 0.2 | N10: 0.765 | O10: 0.287 | P10: 0.108 | Q10: 95.7 | R10: 2.88 | S10: 2.88 | T10: 3.72 | U10: 3.91 | V10: 1
A11: 10 | B11: DL Hall | C11: MIL | D11: 1 | E11: 0 | F11: 0 | G11: 20 | H11: 3 | I11: 38.2 | J11: 6.28 | K11: 3.96 | L11: 0.47 | M11: 0.202 | N11: 0.681 | O11: 0.378 | P11: 0.044 | Q11: 93.9 | R11: 3.49 | S11: 3.54 | T11: 3.73 | U11: 4.85 | V11: 0.4
A12: 11 | B12: Josh Hader | C12: HOU | D12: 6 | E12: 2 | F12: 28 | G12: 48 | H12: 0 | I12: 52.2 | J12: 12.99 | K12: 2.73 | L12: 1.37 | M12: 0.202 | N12: 0.866 | O12: 0.213 | P12: 0.123 | R12: 2.05 | S12: 2 | T12: 3.25 | U12: 3.18 | V12: 1.1
A13: 12 | B13: Taylor Clarke | C13: KCR | D13: 1 | E13: 1 | F13: 1 | G13: 51 | H13: 0 | I13: 55.1 | J13: 7.16 | K13: 1.46 | L13: 1.3 | M13: 0.208 | N13: 0.761 | O13: 0.441 | P13: 0.14 | Q13: 95 | R13: 3.25 | S13: 3.66 | T13: 3.97 | U13: 3.68 | V13: 0.3
A14: 13 | B14: Johan Oviedo | C14: PIT | D14: 2 | E14: 1 | F14: 0 | G14: 9 | H14: 9 | I14: 40.1 | J14: 9.37 | K14: 5.13 | L14: 1.34 | M14: 0.208 | N14: 0.803 | O14: 0.304 | P14: 0.12 | Q14: 95.3 | R14: 3.57 | S14: 4.16 | T14: 4.92 | U14: 4.9 | V14: 0.2
A15: 14 | B15: José Fermin | C15: LAA | D15: 3 | E15: 2 | F15: 0 | G15: 40 | H15: 0 | I15: 34.1 | J15: 10.22 | K15: 6.03 | L15: 2.1 | M15: 0.21 | N15: 0.741 | O15: 0.303 | P15: 0.163 | Q15: 97 | R15: 4.46 | S15: 4.09 | T15: 5.99 | U15: 5.16 | V15: -0.5
A16: 15 | B16: Dennis Santana | C16: PIT | D16: 4 | E16: 5 | F16: 16 | G16: 70 | H16: 0 | I16: 70.1 | J16: 7.68 | K16: 2.18 | L16: 0.64 | M16: 0.211 | N16: 0.807 | O16: 0.384 | P16: 0.058 | Q16: 94.7 | R16: 2.18 | S16: 3.5 | T16: 3.21 | U16: 4.17 | V16: 1.2
A17: 16 | B17: Anthony Bender | C17: MIA | D17: 3 | E17: 5 | F17: 4 | G17: 51 | H17: 0 | I17: 50 | J17: 7.56 | K17: 3.78 | L17: 0.54 | M17: 0.213 | N17: 0.827 | O17: 0.486 | P17: 0.057 | Q17: 96 | R17: 2.16 | S17: 3.55 | T17: 3.62 | U17: 4.47 | V17: 0.4
A18: 17 | B18: Chase Shugart | C18: PIT | D18: 4 | E18: 3 | F18: 0 | G18: 35 | H18: 0 | I18: 45 | J18: 6.2 | K18: 3.4 | L18: 1.2 | M18: 0.214 | N18: 0.775 | O18: 0.333 | P18: 0.097 | Q18: 95.4 | R18: 3.4 | S18: 4.64 | T18: 4.69 | U18: 5.08 | V18: -0.1
A19: 18 | B19: Matt Svanson | C19: STL | D19: 4 | E19: 0 | F19: 0 | G19: 39 | H19: 0 | I19: 60.1 | J19: 10.14 | K19: 2.98 | L19: 0.45 | M19: 0.216 | N19: 0.814 | O19: 0.421 | P19: 0.058 | Q19: 96.6 | R19: 1.94 | S19: 3.08 | T19: 2.72 | U19: 3.4 | V19: 1
A20: 19 | B20: Jacob Webb | C20: TEX | D20: 5 | E20: 4 | F20: 1 | G20: 55 | H20: 0 | I20: 66 | J20: 7.91 | K20: 2.59 | L20: 1.36 | M20: 0.219 | N20: 0.821 | O20: 0.319 | P20: 0.105 | Q20: 93.5 | R20: 3 | S20: 3.23 | T20: 4.3 | U20: 4.55 | V20: 0.2
A21: 20 | B21: Shota Imanaga | C21: CHC | D21: 9 | E21: 8 | F21: 0 | G21: 25 | H21: 25 | I21: 144.2 | J21: 7.28 | K21: 1.62 | L21: 1.93 | M21: 0.219 | N21: 0.815 | O21: 0.292 | P21: 0.136 | Q21: 90.8 | R21: 3.73 | S21: 4.06 | T21: 4.86 | U21: 4.51 | V21: 0.9
A22: 21 | B22: Martín Pérez | C22: CHW | D22: 1 | E22: 6 | F22: 0 | G22: 11 | H22: 10 | I22: 56 | J22: 7.07 | K22: 3.54 | L22: 0.96 | M22: 0.221 | N22: 0.737 | O22: 0.39 | P22: 0.08 | Q22: 89.9 | R22: 3.54 | S22: 5.36 | T22: 4.24 | U22: 4.91 | V22: 0.8
A23: 22 | B23: John Curtiss | C23: ARI | D23: 3 | E23: 2 | F23: 1 | G23: 30 | H23: 0 | I23: 36.2 | J23: 5.89 | K23: 1.23 | L23: 1.23 | M23: 0.224 | N23: 0.593 | O23: 0.291 | P23: 0.1 | Q23: 94.2 | R23: 3.93 | S23: 4.28 | T23: 4.01 | U23: 4.34 | V23: 0
A24: 23 | B24: Tyler Glasnow | C24: LAD | D24: 4 | E24: 3 | F24: 0 | G24: 18 | H24: 18 | I24: 90.1 | J24: 10.56 | K24: 4.28 | L24: 1 | M24: 0.225 | N24: 0.784 | O24: 0.444 | P24: 0.122 | Q24: 95.7 | R24: 3.19 | S24: 3.33 | T24: 3.76 | U24: 3.72 | V24: 1.6
... A45: 44 | B45: Roki Sasaki | C45: LAD | D45: 1 | E45: 1 | F45: 0 | G45: 10 | H45: 8 | I45: 36.1 | J45: 6.94 | K45: 5.45 | L45: 1.49 | M45: 0.235 | N45: 0.794 | O45: 0.389 | P45: 0.136 | Q45: 96.4 | R45: 4.46 | S45: 5.67 | T45: 5.8 | U45: 5.53 | V45: -0.1
A46: 45 | B46: Mason Fluharty | C46: TOR | D46: 5 | E46: 2 | F46: 1 | G46: 55 | H46: 0 | I46: 52.2 | J46: 9.57 | K46: 4.1 | L46: 1.03 | M46: 0.236 | N46: 0.634 | O46: 0.412 | P46: 0.107 | R46: 4.44 | S46: 3.3 | T46: 3.97 | U46: 4.13 | V46: 0.2
A47: 46 | B47: Steven Okert | C47: HOU | D47: 3 | E47: 2 | F47: 1 | G47: 68 | H47: 1 | I47: 71.2 | J47: 10.55 | K47: 2.39 | L47: 0.75 | M47: 0.236 | N47: 0.712 | O47: 0.246 | P47: 0.064 | Q47: 92 | R47: 3.01 | S47: 2.63 | T47: 2.76 | U47: 3.69 | V47: 1.6
A48: 47 | B48: Bryan Woo | C48: SEA | D48: 15 | E48: 7 | F48: 0 | G48: 30 | H48: 30 | I48: 186.2 | J48: 9.55 | K48: 1.74 | L48: 1.25 | M48: 0.238 | N48: 0.804 | O48: 0.408 | P48: 0.128 | Q48: 95.7 | R48: 2.94 | S48: 3.07 | T48: 3.47 | U48: 3.33 | V48: 3.6
A49: 48 | B49: Adrian Morejon | C49: SDP | D49: 13 | E49: 6 | F49: 3 | G49: 75 | H49: 0 | I49: 73.2 | J49: 8.55 | K49: 2.08 | L49: 0.24 | M49: 0.239 | N49: 0.68 | O49: 0.531 | P49: 0.036 | Q49: 96.6 | R49: 2.08 | S49: 2.63 | T49: 2.28 | U49: 3.08 | V49: 2.2
A50: 49 | B50: Pete Fairbanks | C50: TBR | D50: 4 | E50: 5 | F50: 27 | G50: 61 | H50: 0 | I50: 60.1 | J50: 8.8 | K50: 2.69 | L50: 1.04 | M50: 0.239 | N50: 0.775 | O50: 0.451 | P50: 0.109 | Q50: 97.3 | R50: 2.83 | S50: 3.08 | T50: 3.63 | U50: 3.76 | V50: 1
A51: 50 | B51: Ian Hamilton | C51: NYY | D51: 2 | E51: 1 | F51: 0 | G51: 36 | H51: 1 | I51: 40 | J51: 9.45 | K51: 4.95 | L51: 1.13 | M51: 0.24 | N51: 0.705 | O51: 0.378 | P51: 0.119 | Q51: 95.4 | R51: 4.28 | S51: 4.13 | T51: 4.39 | U51: 4.38 | V51: 0
A52: 51 | B52: Mason Miller | C52: 2 Tms | D52: 1 | E52: 2 | F52: 22 | G52: 60 | H52: 0 | I52: 61.2 | J52: 15.18 | K52: 4.09 | L52: 0.73 | M52: 0.24 | N52: 0.76 | O52: 0.404 | P52: 0.114 | Q52: 101.2 | R52: 2.63 | S52: 2.52 | T52: 2.23 | U52: 2.27 | V52: 2
A53: 52 | B53: Eury Pérez | C53: MIA | D53: 7 | E53: 6 | F53: 0 | G53: 20 | H53: 20 | I53: 95.1 | J53: 9.91 | K53: 3.02 | L53: 1.13 | M53: 0.24 | N53: 0.65 | O53: 0.31 | P53: 0.095 | Q53: 97.8 | R53: 4.25 | S53: 3.24 | T53: 3.67 | U53: 4.07 | V53: 1.9
A54: 53 | B54: Tim Hill | C54: NYY | D54: 4 | E54: 4 | F54: 0 | G54: 70 | H54: 0 | I54: 67 | J54: 4.97 | K54: 2.15 | L54: 1.07 | M54: 0.24 | N54: 0.748 | O54: 0.648 | P54: 0.157 | Q54: 89.9 | R54: 3.09 | S54: 3.39 | T54: 4.3 | U54: 3.92 | V54: 0
A55: 54 | B55: Noah Cameron | C55: KCR | D55: 9 | E55: 7 | F55: 0 | G55: 24 | H55: 24 | I55: 138.1 | J55: 7.42 | K55: 2.8 | L55: 1.17 | M55: 0.241 | N55: 0.84 | O55: 0.414 | P55: 0.124 | Q55: 92.4 | R55: 2.99 | S55: 4.08 | T55: 4.18 | U55: 4.1 | V55: 1.8
A56: 55 | B56: Tristan Beck | C56: SFG | D56: 1 | E56: 0 | F56: 2 | G56: 31 | H56: 1 | I56: 56.2 | J56: 6.51 | K56: 2.54 | L56: 1.11 | M56: 0.241 | N56: 0.652 | O56: 0.419 | P56: 0.103 | Q56: 94.7 | R56: 4.61 | S56: 4.44 | T56: 4.25 | U56: 4.49 | V56: 0
A57: 56 | B57: Michael Kelly | C57: ATH | D57: 4 | E57: 4 | F57: 2 | G57: 42 | H57: 0 | I57: 39.2 | J57: 6.58 | K57: 4.31 | L57: 1.13 | M57: 0.241 | N57: 0.778 | O57: 0.417 | P57: 0.1 | Q57: 95.8 | R57: 3.18 | S57: 4.84 | T57: 4.82 | U57: 5.13 | V57: -0.2
A58: 57 | B58: Robert Suarez | C58: SDP | D58: 4 | E58: 6 | F58: 40 | G58: 70 | H58: 0 | I58: 69.2 | J58: 9.69 | K58: 2.07 | L58: 0.78 | M58: 0.241 | N58: 0.724 | O58: 0.362 | P58: 0.085 | Q58: 98.6 | R58: 2.97 | S58: 3.65 | T58: 2.88 | U58: 3.33 | V58: 1.9
... A64: 63 | B64: Justin Slaten | C64: BOS | D64: 2 | E64: 4 | F64: 3 | G64: 36 | H64: 0 | I64: 34 | J64: 6.62 | K64: 2.65 | L64: 0.79 | M64: 0.242 | N64: 0.549 | O64: 0.402 | P64: 0.073 | Q64: 96.9 | R64: 4.24 | S64: 3.49 | T64: 3.69 | U64: 4.41 | V64: 0.4
A65: 64 | B65: Brad Keller | C65: CHC | D65: 4 | E65: 2 | F65: 3 | G65: 68 | H65: 1 | I65: 69.2 | J65: 9.69 | K65: 2.84 | L65: 0.52 | M65: 0.243 | N65: 0.816 | O65: 0.561 | P65: 0.078 | R65: 2.07 | S65: 2.79 | T65: 2.93 | U65: 3.32 | V65: 1.3
...

Sheet BABIP_3yr
A1: # | B1: Name | C1: Team | D1: W | E1: L | F1: SV | G1: G | H1: GS | I1: IP | J1: K/9 | K1: BB/9 | L1: HR/9 | M1: BABIP | N1: LOB% | O1: GB% | P1: HR/FB | Q1: vFA (pi) | R1: ERA | S1: xERA | T1: FIP | U1: xFIP | V1: WAR
A2: 1 | B2: Tyson Miller | C2: 5 Tms | D2: 6 | E2: 1 | F2: 1 | G2: 68 | H2: 0 | I2: 77.1 | J2: 7.45 | K2: 1.98 | L2: 1.05 | M2: 0.212 | N2: 0.785 | O2: 0.281 | P2: 0.087 | R2: 2.79 | S2: 4.03 | T2: 3.93 | U2: 4.48 | V2: 0.5
A3: 2 | B3: Bryan Hudson | C3: 3 Tms | D3: 6 | E3: 2 | F3: 0 | G3: 65 | H3: 0 | I3: 86 | J3: 9.21 | K3: 3.56 | L3: 1.05 | M3: 0.212 | N3: 0.815 | O3: 0.436 | P3: 0.12 | Q3: 91.3 | R3: 2.83 | S3: 3.54 | T3: 4.03 | U3: 4 | V3: 0.6
A4: 3 | B4: Tyler Holton | C4: DET | D4: 16 | E4: 9 | F4: 9 | G4: 195 | H4: 16 | I4: 258.1 | J4: 7.49 | K4: 1.81 | L4: 1.08 | M4: 0.214 | N4: 0.809 | O4: 0.466 | P4: 0.127 | Q4: 91.8 | R4: 2.61 | S4: 3.3 | T4: 3.74 | U4: 3.67 | V4: 2.3
A5: 4 | B5: Shelby Miller | C5: 4 Tms | D5: 13 | E5: 11 | F5: 13 | G5: 135 | H5: 1 | I5: 143.2 | J5: 9.08 | K5: 2.94 | L5: 1.06 | M5: 0.215 | N5: 0.747 | O5: 0.374 | P5: 0.102 | Q5: 94.1 | R5: 3.13 | S5: 3.55 | T5: 3.91 | U5: 4.18 | V5: 1
A6: 5 | B6: Tyler Wells | C6: BAL | D6: 9 | E6: 9 | F6: 1 | G6: 32 | H6: 27 | I6: 155.2 | J6: 8.56 | K6: 2.25 | L6: 1.85 | M6: 0.217 | N6: 0.8 | O6: 0.331 | P6: 0.14 | Q6: 92.7 | R6: 3.76 | S6: 4.19 | T6: 4.83 | U6: 4.53 | V6: 1.2
A7: 6 | B7: Kirby Yates | C7: 3 Tms | D7: 18 | E7: 7 | F7: 41 | G7: 172 | H7: 0 | I7: 163.1 | J7: 11.96 | K7: 4.52 | L7: 1.16 | M7: 0.22 | N7: 0.817 | O7: 0.375 | P7: 0.128 | Q7: 93.3 | R7: 2.98 | S7: 3.32 | T7: 3.86 | U7: 3.77 | V7: 1.7
A8: 7 | B8: Nick Sandlin | C8: 2 Tms | D8: 13 | E8: 7 | F8: 2 | G8: 148 | H8: 1 | I8: 134 | J8: 10.07 | K8: 3.96 | L8: 1.75 | M8: 0.223 | N8: 0.784 | O8: 0.39 | P8: 0.173 | Q8: 92.4 | R8: 3.56 | S8: 4.25 | T8: 5.03 | U8: 4.27 | V8: -0.9
A9: 8 | B9: Brandon Woodruff | C9: MIL | D9: 12 | E9: 3 | F9: 0 | G9: 23 | H9: 23 | I9: 131.2 | J9: 10.73 | K9: 1.98 | L9: 1.23 | M9: 0.223 | N9: 0.812 | O9: 0.352 | P9: 0.119 | Q9: 94.7 | R9: 2.73 | S9: 2.5 | T9: 3.39 | U9: 3.44 | V9: 3.2
A10: 9 | B10: Hunter Strickland | C10: LAA | D10: 4 | E10: 4 | F10: 2 | G10: 91 | H10: 0 | I10: 95.1 | J10: 6.7 | K10: 3.21 | L10: 1.13 | M10: 0.229 | N10: 0.748 | O10: 0.349 | P10: 0.088 | Q10: 94.3 | R10: 3.3 | S10: 3.58 | T10: 4.44 | U10: 4.98 | V10: 0.3
A11: 10 | B11: Josh Hader | C11: 2 Tms | D11: 16 | E11: 13 | F11: 95 | G11: 180 | H11: 0 | I11: 180 | J11: 13.3 | K11: 3.55 | L11: 1.15 | M11: 0.232 | N11: 0.813 | O11: 0.292 | P11: 0.119 | R11: 2.5 | S11: 2.38 | T11: 3.17 | U11: 3.19 | V11: 3.8
A12: 11 | B12: Robert Suarez | C12: SDP | D12: 17 | E12: 12 | F12: 76 | G12: 161 | H12: 0 | I12: 162.1 | J12: 8.76 | K12: 2.33 | L12: 0.94 | M12: 0.233 | N12: 0.745 | O12: 0.407 | P12: 0.102 | Q12: 98.8 | R12: 3.1 | S12: 3.31 | T12: 3.4 | U12: 3.62 | V12: 2.8
A13: 12 | B13: Bowden Francis | C13: TOR | D13: 11 | E13: 13 | F13: 1 | G13: 61 | H13: 27 | I13: 204 | J13: 7.99 | K13: 2.51 | L13: 1.81 | M13: 0.234 | N13: 0.797 | O13: 0.343 | P13: 0.151 | Q13: 93.1 | R13: 3.88 | S13: 4.24 | T13: 5.05 | U13: 4.5 | V13: 0.4
A14: 13 | B14: JT Chargois | C14: 2 Tms | D14: 4 | E14: 1 | F14: 1 | G14: 82 | H14: 5 | I14: 78.2 | J14: 7.44 | K14: 3.55 | L14: 1.03 | M14: 0.235 | N14: 0.831 | O14: 0.464 | P14: 0.113 | Q14: 95.2 | R14: 2.97 | S14: 3.9 | T14: 4.31 | U14: 4.42 | V14: 0.2
A15: 14 | B15: Jacob Webb | C15: 3 Tms | D15: 8 | E15: 10 | F15: 4 | G15: 169 | H15: 0 | I15: 176.1 | J15: 8.83 | K15: 3.88 | L15: 1.02 | M15: 0.235 | N15: 0.776 | O15: 0.341 | P15: 0.092 | Q15: 94 | R15: 3.22 | S15: 3.49 | T15: 4.11 | U15: 4.56 | V15: 1
A16: 15 | B16: Ronel Blanco | C16: HOU | D16: 18 | E16: 11 | F16: 0 | G16: 56 | H16: 45 | I16: 267.2 | J16: 8.94 | K16: 3.9 | L16: 1.38 | M16: 0.236 | N16: 0.811 | O16: 0.377 | P16: 0.131 | Q16: 93.7 | R16: 3.36 | S16: 4.02 | T16: 4.53 | U16: 4.35 | V16: 2.4
A17: 16 | B17: Alex Faedo | C17: DET | D17: 7 | E17: 8 | F17: 0 | G17: 52 | H17: 18 | I17: 122 | J17: 8.34 | K17: 3.54 | L17: 1.55 | M17: 0.236 | N17: 0.753 | O17: 0.375 | P17: 0.147 | Q17: 93.4 | R17: 4.06 | S17: 4.11 | T17: 4.88 | U17: 4.51 | V17: 0.1
A18: 17 | B18: Tommy Kahnle | C18: 2 Tms | D18: 2 | E18: 10 | F18: 12 | G18: 158 | H18: 0 | I18: 146.1 | J18: 8.86 | K18: 4.24 | L18: 1.11 | M18: 0.237 | N18: 0.762 | O18: 0.51 | P18: 0.138 | Q18: 94.3 | R18: 3.26 | S18: 3.67 | T18: 4.31 | U18: 4.1 | V18: 0.1
A19: 18 | B19: Noah Cameron | C19: KCR | D19: 9 | E19: 7 | F19: 0 | G19: 24 | H19: 24 | I19: 138.1 | J19: 7.42 | K19: 2.8 | L19: 1.17 | M19: 0.241 | N19: 0.84 | O19: 0.414 | P19: 0.124 | Q19: 92.4 | R19: 2.99 | S19: 4.08 | T19: 4.18 | U19: 4.1 | V19: 1.8
A20: 19 | B20: Jason Adam | C20: 2 Tms | D20: 19 | E20: 8 | F20: 16 | G20: 195 | H20: 0 | I20: 193.1 | J20: 10.24 | K20: 3.17 | L20: 0.74 | M20: 0.241 | N20: 0.806 | O20: 0.423 | P20: 0.085 | Q20: 95.1 | R20: 2.23 | S20: 3.34 | T20: 3.32 | U20: 3.76 | V20: 3
A21: 20 | B21: Jake Diekman | C21: 3 Tms | D21: 2 | E21: 5 | F21: 4 | G21: 106 | H21: 0 | I21: 88.2 | J21: 10.56 | K21: 6.29 | L21: 1.02 | M21: 0.242 | N21: 0.655 | O21: 0.46 | P21: 0.135 | Q21: 95.3 | R21: 4.16 | S21: 3.97 | T21: 4.61 | U21: 4.49 | V21: -0.4
A22: 21 | B22: Wade Miley | C22: 2 Tms | D22: 10 | E22: 5 | F22: 0 | G22: 28 | H22: 27 | I22: 139.1 | J22: 5.68 | K22: 3.1 | L22: 1.29 | M22: 0.242 | N22: 0.793 | O22: 0.458 | P22: 0.127 | Q22: 90.6 | R22: 3.62 | S22: 4.71 | T22: 4.98 | U22: 4.98 | V22: 0.8
A23: 22 | B23: Jacob deGrom | C23: TEX | D23: 14 | E23: 8 | F23: 0 | G23: 39 | H23: 39 | I23: 213.2 | J23: 10.28 | K23: 1.77 | L23: 1.22 | M23: 0.242 | N23: 0.813 | O23: 0.378 | P23: 0.126 | Q23: 97.8 | R23: 2.86 | S23: 3.06 | T23: 3.28 | U23: 3.19 | V23: 5.2
... A34: 33 | B34: Bryan Woo | C34: SEA | D34: 28 | E34: 15 | F34: 0 | G34: 70 | H34: 70 | I34: 395.2 | J34: 8.92 | K34: 1.82 | L34: 1.21 | M34: 0.246 | N34: 0.772 | O34: 0.406 | P34: 0.118 | Q34: 95.4 | R34: 3.21 | S34: 3.07 | T34: 3.64 | U34: 3.67 | V34: 6.7
A35: 34 | B35: Porter Hodge | C35: CHC | D35: 5 | E35: 3 | F35: 11 | G35: 75 | H35: 0 | I35: 76 | J35: 10.89 | K35: 4.38 | L35: 1.3 | M35: 0.247 | N35: 0.754 | O35: 0.398 | P35: 0.153 | R35: 3.79 | S35: 3.34 | T35: 4.11 | U35: 3.68 | V35: 0.3
A36: 35 | B36: Eduard Bazardo | C36: 2 Tms | D36: 7 | E36: 0 | F36: 0 | G36: 108 | H36: 0 | I36: 122.1 | J36: 9.56 | K36: 2.94 | L36: 0.96 | M36: 0.248 | N36: 0.751 | O36: 0.416 | P36: 0.104 | Q36: 94.8 | R36: 3.31 | S36: 3.12 | T36: 3.44 | U36: 3.65 | V36: 0.9
A37: 36 | B37: Lucas Sims | C37: 3 Tms | D37: 9 | E37: 9 | F37: 4 | G37: 143 | H37: 0 | I37: 122.2 | J37: 9.83 | K37: 6.09 | L37: 1.1 | M37: 0.248 | N37: 0.734 | O37: 0.274 | P37: 0.09 | Q37: 94.5 | R37: 4.7 | S37: 4.41 | T37: 5.11 | U37: 5.67 | V37: 0
A38: 37 | B38: Dennis Santana | C38: 3 Tms | D38: 8 | E38: 6 | F38: 19 | G38: 141 | H38: 0 | I38: 152.2 | J38: 8.31 | K38: 2.65 | L38: 0.65 | M38: 0.249 | N38: 0.713 | O38: 0.365 | P38: 0.061 | Q38: 95.2 | R38: 3.24 | S38: 3.57 | T38: 3.29 | U38: 4.18 | V38: 2.2
A39: 38 | B39: Kenley Jansen | C39: 2 Tms | D39: 12 | E39: 12 | F39: 85 | G39: 167 | H39: 0 | I39: 158.1 | J39: 9.72 | K39: 3.18 | L39: 0.97 | M39: 0.25 | N39: 0.767 | O39: 0.27 | P39: 0.075 | R39: 3.13 | S39: 3.43 | T39: 3.55 | U39: 4.41 | V39: 3.1
A40: 39 | B40: Hunter Gaddis | C40: CLE | D40: 10 | E40: 6 | F40: 3 | G40: 162 | H40: 7 | I40: 183.1 | J40: 8 | K40: 2.41 | L40: 0.88 | M40: 0.251 | N40: 0.795 | O40: 0.346 | P40: 0.074 | Q40: 94.8 | R40: 2.8 | S40: 3.33 | T40: 3.62 | U40: 4.42 | V40: 2.6
A41: 40 | B41: Eury Pérez | C41: MIA | D41: 12 | E41: 12 | F41: 0 | G41: 39 | H41: 39 | I41: 186.2 | J41: 10.27 | K41: 3.04 | L41: 1.3 | M41: 0.251 | N41: 0.74 | O41: 0.283 | P41: 0.108 | Q41: 97.7 | R41: 3.71 | S41: 3.42 | T41: 3.88 | U41: 4.15 | V41: 3.4
A42: 41 | B42: Ryan Pepiot | C42: 2 Tms | D42: 21 | E42: 21 | F42: 0 | G42: 65 | H42: 60 | I42: 339.2 | J42: 9.19 | K42: 3.02 | L42: 1.32 | M42: 0.251 | N42: 0.768 | O42: 0.369 | P42: 0.127 | Q42: 95 | R42: 3.55 | S42: 3.73 | T42: 4.18 | U42: 4.05 | V42: 4.4
A43: 42 | B43: Alexis Díaz | C43: 3 Tms | D43: 12 | E43: 11 | F43: 65 | G43: 149 | H43: 0 | I43: 141.1 | J43: 10.06 | K43: 5.03 | L43: 1.02 | M43: 0.251 | N43: 0.689 | O43: 0.342 | P43: 0.104 | Q43: 94.3 | R43: 4.08 | S43: 3.87 | T43: 4.56 | U43: 4.8 | V43: 1.3
A44: 43 | B44: Bryce Jarvis | C44: ARI | D44: 3 | E44: 3 | F44: 1 | G44: 67 | H44: 1 | I44: 105 | J44: 6.09 | K44: 4.46 | L44: 1.03 | M44: 0.251 | N44: 0.76 | O44: 0.412 | P44: 0.096 | Q44: 95.3 | R44: 3.69 | S44: 5.09 | T44: 4.97 | U44: 5.33 | V44: -0.7
A45: 44 | B45: Hayden Wesneski | C45: 2 Tms | D45: 7 | E45: 14 | F45: 0 | G45: 68 | H45: 24 | I45: 189 | J45: 8.52 | K45: 2.81 | L45: 1.86 | M45: 0.251 | N45: 0.727 | O45: 0.415 | P45: 0.185 | Q45: 94.5 | R45: 4.33 | S45: 4.66 | T45: 5.02 | U45: 4.11 | V45: 0
A46: 45 | B46: Chris Devenski | C46: 3 Tms | D46: 8 | E46: 5 | F46: 0 | G46: 70 | H46: 1 | I46: 85.2 | J46: 8.4 | K46: 3.15 | L46: 1.68 | M46: 0.251 | N46: 0.638 | O46: 0.355 | P46: 0.14 | Q46: 93.5 | R46: 4.73 | S46: 4.78 | T46: 4.92 | U46: 4.59 | V46: 0
A47: 46 | B47: Landon Knack | C47: LAD | D47: 6 | E47: 7 | F47: 2 | G47: 25 | H47: 19 | I47: 111.1 | J47: 8.97 | K47: 2.99 | L47: 1.94 | M47: 0.252 | N47: 0.818 | O47: 0.311 | P47: 0.158 | Q47: 93.4 | R47: 4.12 | S47: 4.59 | T47: 5.09 | U47: 4.37 | V47: 0.4
A48: 47 | B48: Devin Williams | C48: 2 Tms | D48: 13 | E48: 9 | F48: 68 | G48: 150 | H48: 0 | I48: 142.1 | J48: 13.59 | K48: 4.05 | L48: 0.63 | M48: 0.252 | N48: 0.717 | O48: 0.457 | P48: 0.097 | Q48: 94.2 | R48: 2.91 | S48: 2.75 | T48: 2.58 | U48: 2.81 | V48: 4
A49: 48 | B49: Jordan Lyles | C49: KCR | D49: 6 | E49: 17 | F49: 0 | G49: 36 | H49: 31 | I49: 182.2 | J49: 6.06 | K49: 2.32 | L49: 1.92 | M49: 0.252 | N49: 0.573 | O49: 0.337 | P49: 0.137 | Q49: 91.4 | R49: 6.11 | S49: 4.89 | T49: 5.55 | U49: 5.35 | V49: 0.2
A50: 49 | B50: Buck Farmer | C50: CIN | D50: 7 | E50: 7 | F50: 4 | G50: 132 | H50: 1 | I50: 146 | J50: 8.63 | K50: 3.58 | L50: 1.11 | M50: 0.252 | N50: 0.773 | O50: 0.345 | P50: 0.1 | Q50: 93.7 | R50: 3.64 | S50: 4.09 | T50: 4.31 | U50: 4.67 | V50: 1.1
...
