Workbook

Sheet Ideal_Lineup
A1: Round | B1: First Pick | C1: Back Up | D1: Back Up 2 | E1: Back Up 3
A2: 1 | B2: Corbin Carroll | C2: Julio Rodriguez | D2: Ronald Acuna Jr. | E2: Fernando Tatis Jr
A3: 2 | B3: Pete Alonso | C3: Vlad Guerreo Jr | D3: Fernando Tatis Jr
A4: 3 | B4: James Wood | C4: Pete Crow-Armstrong | D4: Cristopher Sanchez | I4: Ideal Round | J4: High Round | K4: Low Round | L4: Target | M4: Reach | N4: Fallback
A5: 4 | B5: Manny Machado | C5: Chris Sale | D5: Jacob DeGrom | E5: Bryan Woo | H5: c | I5: 7 | J5: 5 | K5: 7 | L5: Agustin Ramirez | M5: Ben Rice/Shea Langeliers | N5: Agustin Ramirez
A6: 5 | B6: Matt Olson | C6: Bryce Harper | D6: Ben Rice | E6: Shea Langiliers | H6: 1b | I6: 2 | J6: 2 | K6: 5 | L6: Pete Alonso/Vlad Jr | M6: Pete Alonso/Vlad Jr | N6: Matt Olson/Bryce Harper
A7: 6 | B7: Jackson Merrill | C7: Rafael Devers | D7: Augustin Ramirez | H7: 2b | I7: 15 | J7: 3 | K7: 20 | L7: Brandon Lowe | M7: Ketel Marte | N7: Marcus Seimen
A8: 7 | B8: Augustin Ramirez | C8: Jesus Luzardo | D8: Dylan Cease | E8: Jarren Duran | H8: ss | I8: 9 | J8: 3 | K8: 18 | L8: Corey Seager | M8: Trea Turner | N8: Ezequiel Tovar/Konnor Griffin
A9: 8 | B9: Shohei Ohtani | H9: 3b | I9: 4 | J9: 3 | K9: 16 | L9: Manny Machado | M9: Manny Machado | N9: Jordan Westberg
A10: 9 | B10: Corey Seager | H10: of | I10: 1 | J10: 1 | K10: 1 | L10: Corbin Carroll | M10: Ronald Acuna Jr. | N10: Julio Rodriguez/Fernando Tatis Jr.
A11: 10 | B11: Nick Lodolo | H11: of | I11: 3 | J11: 2 | K11: 6 | L11: James Wood | M11: James Wood/Pete Crow-Armstrong | N11: Jackson Merrill
A12: 11 | B12: Jo Adell | H12: of | I12: 11 | J12: 6 | K12: 17 | L12: Jo Adell | M12: Jackson Merrill | N12: Daylen Lile
A13: 12 | B13: Ranger Suarez | H13: util | I13: 5 | J13: 5 | K13: 11 | L13: Matt Olson/Bryce Harper
A14: 13 | B14: Shota Imanaga | H14: util | I14: 6 | J14: 11 | K14: 20 | L14: Jackson Merrill | M14: Trevor Story
A15: 14 | B15: MacKenzie Gore | H15: sp | I15: 8 | J15: 4 | K15: 8 | L15: Shohei Ohtani | M15: Chris Sale/Jacob DeGrom/Bryan Woo
A16: 15 | B16: Brandon Lowe | H16: sp | I16: 10 | J16: 9 | K16: 12 | L16: Nick Lodolo
A17: 16 | B17: Will Vest | H17: rp | I17: 16 | J17: 12 | K17: 19 | L17: Will Vest
A18: 17 | B18: Daylen Lile | H18: rp | I18: 20 | J18: 15 | K18: 20 | L18: Jason Adam
A19: 18 | B19: Kris Bubic | H19: p | I19: 12 | J19: 11 | K19: 17 | L19: Ranger Suarez
A20: 19 | B20: Mickey Moniak | H20: p | I20: 13 | J20: 13 | K20: 18 | L20: Shota Imanaga
A21: 20 | B21: Jason Adam | H21: p | I21: 14 | J21: 15 | K21: 19 | L21: MacKenzie Gore
A22: 21 | B22: Garrett Cleavinger | H22: p | I22: 18 | J22: 16 | K22: 20 | L22: Kris Bubic
A23: 22 | B23: Dylan Lee | H23: util | I23: 17 | J23: 17 | K23: 22 | L23: Daylen Lile | M23: Daylen Lile | N23: Mickey Moniak
A24: 23 | B24: Bennett Sousa | F24: ? | H24: util | I24: 19 | J24: 18 | K24: 23 | L24: Mickey Moniak | M24: Daylen Lile | N24: Jerar Encarnacion
H25: p | I25: 21 | J25: 19 | K25: 21 | L25: Garrett Cleavinger
H26: p | I26: 22 | J26: 20 | K26: 22 | L26: Dylan Lee
H27: p | I27: 23 | J27: 21 | K27: 23 | L27: Bennett Sousa
L29: Also consider
A31: Name | B31: Position | C31: Sum(great_season_probability) | D31: ADP | E31: Round | F31: BABIP_Expectation_Batter | G31: BABIP_Expectation_Pitcher
A32: Shohei Ohtani | B32: DH | C32: 0.92943645 | D32: 1.5 | E32: 1 | F32: Same | G32: #N/A
A33: Aaron Judge | B33: OF/DH | C33: 0.9162953 | D33: 3.4 | E33: 1 | F33: Regression | G33: #N/A
A34: Vladimir Guerrero Jr. | B34: 1B/DH | C34: 0.9117822 | D34: 14.4 | E34: 2 | F34: Regression | G34: #N/A
A35: Fernando Tatis Jr. | B35: OF | C35: 0.9117414 | D35: 10.6 | E35: 1 | F35: Regression | G35: #N/A
A36: Reed Garrett | B36: RP | C36: 0.9159347 | D36: #N/A | E36: #N/A | F36: #N/A | G36: #N/A
A37: Juan Soto | B37: OF | C37: 0.86973935 | D37: 7.8 | E37: 1 | F37: Regression | G37: #N/A
A38: Dedniel Nunez | B38: RP | C38: 0.898492 | D38: #N/A | E38: #N/A | F38: #N/A | G38: #N/A
A39: Yordan Alvarez | B39: OF/DH | C39: 0.8654861 | D39: 17.6 | E39: 2 | F39: Same | G39: #N/A
A40: Jake Cousins | B40: RP | C40: 0.8984478 | D40: #N/A | E40: #N/A | F40: #N/A | G40: #N/A
A41: Rafael Devers | B41: 3B | C41: 0.8580056 | D41: 34.8 | E41: 3 | F41: Same | G41: #N/A
A42: Tommy Kahnle | B42: RP | C42: 0.89481205 | D42: 240 | E42: 20 | F42: #N/A | G42: #N/A
...

Sheet Combined_Tiers
A1: Name | B1: Position | C1: great_season_probability | D1: ADP | E1: Round
A2: Aaron Judge | B2: OF/DH | C2: 0.9083965 | D2: 1.9 | E2: 1
A3: Bobby Witt Jr. | B3: SS | C3: 0.75887525 | D3: 2.9 | E3: 1
A4: Shohei Ohtani | B4: DH | C4: 0.7436603 | D4: 1.3 | E4: 1
A5: Tarik Skubal | B5: SP | C5: 0.7353988 | D5: 6.9 | E5: 1
A6: Julio Rodriguez | B6: OF | C6: 0.6871629 | D6: 10.6 | E6: 1
A7: Ronald Acuna Jr. | B7: OF | C7: 0.640605 | D7: 6.3 | E7: 1
A8: Juan Soto | B8: OF | C8: 0.6325008 | D8: 4.5 | E8: 1
A9: Paul Skenes | B9: SP | C9: 0.47025585 | D9: 10.2 | E9: 1
A10: Jose Ramirez | B10: 3B/DH | C10: 0.35408595 | D10: 5.8 | E10: 1
A11: Elly De La Cruz | B11: SS | C11: 0.31645152 | D11: 8.5 | E11: 1
A12: Garrett Crochet | B12: SP | C12: 0.27405342 | D12: 11.4 | E12: 1
A13: Vladimir Guerrero Jr. | B13: 1B/DH | C13: 0.83745563 | D13: 18 | E13: 2
... A180: Joey Ortiz | B180: SS | C180: 0.07513961 | D180: 740.6 | E180: 62
A181: Ben Brown | B181: SP | C181: 0.252659 | D181: 999 | E181: =_xlfn.CEILING.MATH(D181/12) -> 84
A182: Max Kepler | B182: OF | C182: 0.24579903 | D182: 999 | E182: =_xlfn.CEILING.MATH(D182/12) -> 84
A183: Heriberto Hernandez | B183: OF/DH | C183: 0.22174667 | D183: 999 | E183: =_xlfn.CEILING.MATH(D183/12) -> 84
A184: Myles Straw | B184: OF | C184: 0.19491282 | D184: 999 | E184: =_xlfn.CEILING.MATH(D184/12) -> 84
A185: Dean Kremer | B185: SP | C185: 0.16272049 | D185: 999 | E185: =_xlfn.CEILING.MATH(D185/12) -> 84
A186: Tommy Pham | B186: OF | C186: 0.1259256 | D186: 999 | E186: =_xlfn.CEILING.MATH(D186/12) -> 84
A187: Eric Lauer | B187: SP | C187: 0.10947341 | D187: 999 | E187: =_xlfn.CEILING.MATH(D187/12) -> 84
A188: Eric Wagaman | B188: 1B/OF | C188: 0.10534485 | D188: 999 | E188: =_xlfn.CEILING.MATH(D188/12) -> 84
A189: Andrew McCutchen | B189: DH | C189: 0.09942715 | D189: 999 | E189: =_xlfn.CEILING.MATH(D189/12) -> 84
A190: Mike Yastrzemski | B190: OF | C190: 0.09530265 | D190: 999 | E190: =_xlfn.CEILING.MATH(D190/12) -> 84
A191: Gabriel Arias | B191: 2B/SS | C191: 0.088377364 | D191: 999 | E191: =_xlfn.CEILING.MATH(D191/12) -> 84
A192: Alek Thomas | B192: OF | C192: 0.087574296 | D192: 999 | E192: =_xlfn.CEILING.MATH(D192/12) -> 84
... A196: Ty France | B196: 1B | C196: 0.078541756 | D196: 999 | E196: =_xlfn.CEILING.MATH(D196/12) -> 84
A197: Brooks Baldwin | B197: #N/A | C197: 0.49043992 | D197: #N/A | E197: #N/A
A198: Randal Grichuk | B198: #N/A | C198: 0.4846786 | D198: #N/A | E198: #N/A
A199: Will Benson | B199: #N/A | C199: 0.41992894 | D199: #N/A | E199: #N/A
A200: Tyrone Taylor | B200: #N/A | C200: 0.3957435 | D200: #N/A | E200: #N/A
A201: Luke Raley | B201: #N/A | C201: 0.30508044 | D201: #N/A | E201: #N/A
A202: Jake Bauers | B202: #N/A | C202: 0.27564982 | D202: #N/A | E202: #N/A
A203: Nick Gonzales | B203: #N/A | C203: 0.1985416 | D203: #N/A | E203: #N/A
A204: Otto Kemp | B204: #N/A | C204: 0.15048069 | D204: #N/A | E204: #N/A
A205: Blaze Alexander | B205: #N/A | C205: 0.15048069 | D205: #N/A | E205: #N/A
A206: Ryan Mountcastle | B206: #N/A | C206: 0.10231702 | D206: #N/A | E206: #N/A
A207: Joc Pederson | B207: #N/A | C207: 0.09732419 | D207: #N/A | E207: #N/A
A208: Wenceel Perez | B208: #N/A | C208: 0.09476013 | D208: #N/A | E208: #N/A
... A212: Christopher Morel | B212: #N/A | C212: 0.087543264 | D212: #N/A | E212: #N/A

Sheet Batter_Tiers
A1: last_name, first_name | B1: great_season_probability | G1: Name | H1: Position | I1: Sum(great_season_probability) | J1: ADP | K1: Round | N1: Watch List | O1: C | P1: 1B | Q1: 2B | R1: 3B | S1: SS | T1: OF | U1: Util | V1: SP | W1: RP
A2: Alonso, Pete | B2: 0.9226731 | E2: =LEFT(A2, FIND(",", A2) - 1) -> Alonso | F2: =TRIM(MID(A2, FIND(",", A2) + 1, LEN(A2))) -> Pete | G2: =F2 & " " & E2 -> Pete Alonso | H2: =VLOOKUP(G2,ADP!$B$1:$K$646,3,FALSE) -> 1B | I2: =B2 -> 0.9226731 | J2: =VLOOKUP(G2,ADP!$B$1:$K$646,4,FALSE) -> 25 | K2: =_xlfn.CEILING.MATH(J2/12) -> 3 | O2: Salvador Perez | P2: Christian Walker | Q2: Jordan Westburg | R2: Rafael Devers | S2: Bobby Witt Jr. | T2: Aaron Judge | U2: Shohei Ohtani
A3: Judge, Aaron | B3: 0.9083965 | E3: =LEFT(A3, FIND(",", A3) - 1) -> Judge | F3: =TRIM(MID(A3, FIND(",", A3) + 1, LEN(A3))) -> Aaron | G3: =F3 & " " & E3 -> Aaron Judge | H3: =VLOOKUP(G3,ADP!$B$1:$K$646,3,FALSE) -> OF/DH | I3: =B3 -> 0.9083965 | J3: =VLOOKUP(G3,ADP!$B$1:$K$646,4,FALSE) -> 1.9 | K3: =_xlfn.CEILING.MATH(J3/12) -> 1 | O3: William Contreras | P3: Matt Olson | Q3: Ketel Marte | R3: Austin Riley | S3: Corey Seager | T3: Vladimir Guerrero Jr.
A4: Gonzalez, Romy | B4: 0.8846713 | E4: =LEFT(A4, FIND(",", A4) - 1) -> Gonzalez | F4: =TRIM(MID(A4, FIND(",", A4) + 1, LEN(A4))) -> Romy | G4: =F4 & " " & E4 -> Romy Gonzalez | H4: =VLOOKUP(G4,ADP!$B$1:$K$646,3,FALSE) -> 1B/2B | I4: =B4 -> 0.8846713 | J4: =VLOOKUP(G4,ADP!$B$1:$K$646,4,FALSE) -> 719.2 | K4: =_xlfn.CEILING.MATH(J4/12) -> 60 | O4: Wilson Contreras | P4: Tyler Soderstrom | Q4: Brandon Lowe | R4: Matt Chapman | S4: Oneil Cruz | T4: Fernando Tatis Jr.
A5: Seager, Corey | B5: 0.86515254 | E5: =LEFT(A5, FIND(",", A5) - 1) -> Seager | F5: =TRIM(MID(A5, FIND(",", A5) + 1, LEN(A5))) -> Corey | G5: =F5 & " " & E5 -> Corey Seager | H5: =VLOOKUP(G5,ADP!$B$1:$K$646,3,FALSE) -> SS | I5: =B5 -> 0.86515254 | J5: =VLOOKUP(G5,ADP!$B$1:$K$646,4,FALSE) -> 99.5 | K5: =_xlfn.CEILING.MATH(J5/12) -> 9 | P5: Bryce Harper | Q5: Marcus Semien | R5: Gunnar Henderson | S5: Francisco Lindor | T5: Juan Soto
A6: Guerrero Jr., Vladimir | B6: 0.83745563 | E6: =LEFT(A6, FIND(",", A6) - 1) -> Guerrero Jr. | F6: =TRIM(MID(A6, FIND(",", A6) + 1, LEN(A6))) -> Vladimir | G6: =F6 & " " & E6 -> Vladimir Guerrero Jr. | H6: =VLOOKUP(G6,ADP!$B$1:$K$646,3,FALSE) -> 1B/DH | I6: =B6 -> 0.83745563 | J6: =VLOOKUP(G6,ADP!$B$1:$K$646,4,FALSE) -> 18 | K6: =_xlfn.CEILING.MATH(J6/12) -> 2 | P6: Pete Alonso | Q6: Bryson Stott | R6: Manny Machado | S6: Ezequiel Tovar | T6: Yordan Alvarez
A7: Olson, Matt | B7: 0.82606506 | E7: =LEFT(A7, FIND(",", A7) - 1) -> Olson | F7: =TRIM(MID(A7, FIND(",", A7) + 1, LEN(A7))) -> Matt | G7: =F7 & " " & E7 -> Matt Olson | H7: =VLOOKUP(G7,ADP!$B$1:$K$646,3,FALSE) -> 1B | I7: =B7 -> 0.82606506 | J7: =VLOOKUP(G7,ADP!$B$1:$K$646,4,FALSE) -> 50.9 | K7: =_xlfn.CEILING.MATH(J7/12) -> 5 | P7: Luke Raley | Q7: Mookie Betts | R7: Miguel Vargas | S7: Elly De La Cruz | T7: Mike Trout
A8: Carroll, Corbin | B8: 0.7911162 | E8: =LEFT(A8, FIND(",", A8) - 1) -> Carroll | F8: =TRIM(MID(A8, FIND(",", A8) + 1, LEN(A8))) -> Corbin | G8: =F8 & " " & E8 -> Corbin Carroll | H8: =VLOOKUP(G8,ADP!$B$1:$K$646,3,FALSE) -> OF | I8: =B8 -> 0.7911162 | J8: =VLOOKUP(G8,ADP!$B$1:$K$646,4,FALSE) -> 12.2 | K8: =_xlfn.CEILING.MATH(J8/12) -> 2 | P8: Yandy Díaz | R8: José Ramírez | S8: Masyn Winn | T8: Giancarlo Stanton
A9: Witt Jr., Bobby | B9: 0.75887525 | E9: =LEFT(A9, FIND(",", A9) - 1) -> Witt Jr. | F9: =TRIM(MID(A9, FIND(",", A9) + 1, LEN(A9))) -> Bobby | G9: =F9 & " " & E9 -> Bobby Witt Jr. | H9: =VLOOKUP(G9,ADP!$B$1:$K$646,3,FALSE) -> SS | I9: =B9 -> 0.75887525 | J9: =VLOOKUP(G9,ADP!$B$1:$K$646,4,FALSE) -> 2.9 | K9: =_xlfn.CEILING.MATH(J9/12) -> 1 | S9: =REPLACE(_xlfn.CONCAT(R9," ",Q9), 1, 1,"") | T9: Jackson Merrill
A10: Lile, Daylen | B10: 0.75545996 | E10: =LEFT(A10, FIND(",", A10) - 1) -> Lile | F10: =TRIM(MID(A10, FIND(",", A10) + 1, LEN(A10))) -> Daylen | G10: =F10 & " " & E10 -> Daylen Lile | H10: =VLOOKUP(G10,ADP!$B$1:$K$646,3,FALSE) -> OF | I10: =B10 -> 0.75545996 | J10: =VLOOKUP(G10,ADP!$B$1:$K$646,4,FALSE) -> 198.3 | K10: =_xlfn.CEILING.MATH(J10/12) -> 17 | T10: Matt Olson
A11: Ohtani, Shohei | B11: 0.7436603 | E11: =LEFT(A11, FIND(",", A11) - 1) -> Ohtani | F11: =TRIM(MID(A11, FIND(",", A11) + 1, LEN(A11))) -> Shohei | G11: =F11 & " " & E11 -> Shohei Ohtani | H11: =VLOOKUP(G11,ADP!$B$1:$K$646,3,FALSE) -> DH | I11: =B11 -> 0.7436603 | J11: =VLOOKUP(G11,ADP!$B$1:$K$646,4,FALSE) -> 1.3 | K11: =_xlfn.CEILING.MATH(J11/12) -> 1 | T11: Michael Harris II
A12: Harper, Bryce | B12: 0.73556554 | E12: =LEFT(A12, FIND(",", A12) - 1) -> Harper | F12: =TRIM(MID(A12, FIND(",", A12) + 1, LEN(A12))) -> Bryce | G12: =F12 & " " & E12 -> Bryce Harper | H12: =VLOOKUP(G12,ADP!$B$1:$K$646,3,FALSE) -> 1B | I12: =B12 -> 0.73556554 | J12: =VLOOKUP(G12,ADP!$B$1:$K$646,4,FALSE) -> 50.7 | K12: =_xlfn.CEILING.MATH(J12/12) -> 5 | T12: Kyle Tucker
A13: Tatis Jr., Fernando | B13: 0.7162315 | E13: =LEFT(A13, FIND(",", A13) - 1) -> Tatis Jr. | F13: =TRIM(MID(A13, FIND(",", A13) + 1, LEN(A13))) -> Fernando | G13: =F13 & " " & E13 -> Fernando Tatis Jr. | H13: =VLOOKUP(G13,ADP!$B$1:$K$646,3,FALSE) -> OF | I13: =B13 -> 0.7162315 | J13: =VLOOKUP(G13,ADP!$B$1:$K$646,4,FALSE) -> 14.8 | K13: =_xlfn.CEILING.MATH(J13/12) -> 2 | T13: Jackson Chourio
A14: Rice, Ben | B14: 0.69049954 | E14: =LEFT(A14, FIND(",", A14) - 1) -> Rice | F14: =TRIM(MID(A14, FIND(",", A14) + 1, LEN(A14))) -> Ben | G14: =F14 & " " & E14 -> Ben Rice | H14: =VLOOKUP(G14,ADP!$B$1:$K$646,3,FALSE) -> C/1B/DH | I14: =B14 -> 0.69049954 | J14: =VLOOKUP(G14,ADP!$B$1:$K$646,4,FALSE) -> 50.5 | K14: =_xlfn.CEILING.MATH(J14/12) -> 5 | T14: Matt Wallner
A15: Schwarber, Kyle | B15: 0.68764704 | E15: =LEFT(A15, FIND(",", A15) - 1) -> Schwarber | F15: =TRIM(MID(A15, FIND(",", A15) + 1, LEN(A15))) -> Kyle | G15: =F15 & " " & E15 -> Kyle Schwarber | H15: =VLOOKUP(G15,ADP!$B$1:$K$646,3,FALSE) -> DH | I15: =B15 -> 0.68764704 | J15: =VLOOKUP(G15,ADP!$B$1:$K$646,4,FALSE) -> 24.5 | K15: =_xlfn.CEILING.MATH(J15/12) -> 3 | T15: Julio Rodríguez
A16: Rodriguez, Julio | B16: 0.6871629 | E16: =LEFT(A16, FIND(",", A16) - 1) -> Rodriguez | F16: =TRIM(MID(A16, FIND(",", A16) + 1, LEN(A16))) -> Julio | G16: =F16 & " " & E16 -> Julio Rodriguez | H16: =VLOOKUP(G16,ADP!$B$1:$K$646,3,FALSE) -> OF | I16: =B16 -> 0.6871629 | J16: =VLOOKUP(G16,ADP!$B$1:$K$646,4,FALSE) -> 10.6 | K16: =_xlfn.CEILING.MATH(J16/12) -> 1 | T16: Leody Taveras
A17: Wood, James | B17: 0.68579453 | E17: =LEFT(A17, FIND(",", A17) - 1) -> Wood | F17: =TRIM(MID(A17, FIND(",", A17) + 1, LEN(A17))) -> James | G17: =F17 & " " & E17 -> James Wood | H17: =VLOOKUP(G17,ADP!$B$1:$K$646,3,FALSE) -> OF/DH | I17: =B17 -> 0.68579453 | J17: =VLOOKUP(G17,ADP!$B$1:$K$646,4,FALSE) -> 33 | K17: =_xlfn.CEILING.MATH(J17/12) -> 3 | T17: Jesús Sánchez
A18: Langeliers, Shea | B18: 0.67310816 | E18: =LEFT(A18, FIND(",", A18) - 1) -> Langeliers | F18: =TRIM(MID(A18, FIND(",", A18) + 1, LEN(A18))) -> Shea | G18: =F18 & " " & E18 -> Shea Langeliers | H18: =VLOOKUP(G18,ADP!$B$1:$K$646,3,FALSE) -> C | I18: =B18 -> 0.67310816 | J18: =VLOOKUP(G18,ADP!$B$1:$K$646,4,FALSE) -> 54 | K18: =_xlfn.CEILING.MATH(J18/12) -> 5 | T18: Oneil Cruz
A19: Moniak, Mickey | B19: 0.664478 | E19: =LEFT(A19, FIND(",", A19) - 1) -> Moniak | F19: =TRIM(MID(A19, FIND(",", A19) + 1, LEN(A19))) -> Mickey | G19: =F19 & " " & E19 -> Mickey Moniak | H19: =VLOOKUP(G19,ADP!$B$1:$K$646,3,FALSE) -> OF | I19: =B19 -> 0.664478 | J19: =VLOOKUP(G19,ADP!$B$1:$K$646,4,FALSE) -> 252.6 | K19: =_xlfn.CEILING.MATH(J19/12) -> 22 | T19: Anthony Santander
A20: Devers, Rafael | B20: 0.6469967 | E20: =LEFT(A20, FIND(",", A20) - 1) -> Devers | F20: =TRIM(MID(A20, FIND(",", A20) + 1, LEN(A20))) -> Rafael | G20: =F20 & " " & E20 -> Rafael Devers | H20: =VLOOKUP(G20,ADP!$B$1:$K$646,3,FALSE) -> 1B/DH | I20: =B20 -> 0.6469967 | J20: =VLOOKUP(G20,ADP!$B$1:$K$646,4,FALSE) -> 55.5 | K20: =_xlfn.CEILING.MATH(J20/12) -> 5 | T20: Wyatt Langford
A21: Acuna Jr., Ronald | B21: 0.640605 | E21: =LEFT(A21, FIND(",", A21) - 1) -> Acuna Jr. | F21: =TRIM(MID(A21, FIND(",", A21) + 1, LEN(A21))) -> Ronald | G21: =F21 & " " & E21 -> Ronald Acuna Jr. | H21: =VLOOKUP(G21,ADP!$B$1:$K$646,3,FALSE) -> OF | I21: =B21 -> 0.640605 | J21: =VLOOKUP(G21,ADP!$B$1:$K$646,4,FALSE) -> 6.3 | K21: =_xlfn.CEILING.MATH(J21/12) -> 1 | T21: Kyle Schwarber
... A24: Bell, Josh | B24: 0.58078927 | E24: =LEFT(A24, FIND(",", A24) - 1) -> Bell | F24: =TRIM(MID(A24, FIND(",", A24) + 1, LEN(A24))) -> Josh | G24: =F24 & " " & E24 -> Josh Bell | H24: =VLOOKUP(G24,ADP!$B$1:$K$646,3,FALSE) -> 1B/DH | I24: =B24 -> 0.58078927 | J24: =VLOOKUP(G24,ADP!$B$1:$K$646,4,FALSE) -> 674.8 | K24: =_xlfn.CEILING.MATH(J24/12) -> 57 | T24: Sam Hilliard
A25: Stanton, Giancarlo | B25: 0.57851666 | E25: =LEFT(A25, FIND(",", A25) - 1) -> Stanton | F25: =TRIM(MID(A25, FIND(",", A25) + 1, LEN(A25))) -> Giancarlo | G25: =F25 & " " & E25 -> Giancarlo Stanton | H25: =VLOOKUP(G25,ADP!$B$1:$K$646,3,FALSE) -> OF/DH | I25: =B25 -> 0.57851666 | J25: =VLOOKUP(G25,ADP!$B$1:$K$646,4,FALSE) -> 251.9 | K25: =_xlfn.CEILING.MATH(J25/12) -> 21 | P25: come back make a new table with player, position, probability, and adp so we can sort with it | T25: Brenton Doyle
A26: Merrill, Jackson | B26: 0.5749441 | E26: =LEFT(A26, FIND(",", A26) - 1) -> Merrill | F26: =TRIM(MID(A26, FIND(",", A26) + 1, LEN(A26))) -> Jackson | G26: =F26 & " " & E26 -> Jackson Merrill | H26: =VLOOKUP(G26,ADP!$B$1:$K$646,3,FALSE) -> OF | I26: =B26 -> 0.5749441 | J26: =VLOOKUP(G26,ADP!$B$1:$K$646,4,FALSE) -> 70.8 | K26: =_xlfn.CEILING.MATH(J26/12) -> 6 | P26: goal will be to optimize for great season and adp | T26: Luis Robert Jr.
A27: Machado, Manny | B27: 0.5433981 | E27: =LEFT(A27, FIND(",", A27) - 1) -> Machado | F27: =TRIM(MID(A27, FIND(",", A27) + 1, LEN(A27))) -> Manny | G27: =F27 & " " & E27 -> Manny Machado | H27: =VLOOKUP(G27,ADP!$B$1:$K$646,3,FALSE) -> 3B | I27: =B27 -> 0.5433981 | J27: =VLOOKUP(G27,ADP!$B$1:$K$646,4,FALSE) -> 39.2 | K27: =_xlfn.CEILING.MATH(J27/12) -> 4 | T27: Brent Rooker Jr.
A28: Crow-Armstrong, Pete | B28: 0.5214958 | E28: =LEFT(A28, FIND(",", A28) - 1) -> Crow-Armstrong | F28: =TRIM(MID(A28, FIND(",", A28) + 1, LEN(A28))) -> Pete | G28: =F28 & " " & E28 -> Pete Crow-Armstrong | H28: =VLOOKUP(G28,ADP!$B$1:$K$646,3,FALSE) -> OF | I28: =B28 -> 0.5214958 | J28: =VLOOKUP(G28,ADP!$B$1:$K$646,4,FALSE) -> 31 | K28: =_xlfn.CEILING.MATH(J28/12) -> 3 | T28: Daulton Varsho
A29: Diaz, Yandy | B29: 0.50874186 | E29: =LEFT(A29, FIND(",", A29) - 1) -> Diaz | F29: =TRIM(MID(A29, FIND(",", A29) + 1, LEN(A29))) -> Yandy | G29: =F29 & " " & E29 -> Yandy Diaz | H29: =VLOOKUP(G29,ADP!$B$1:$K$646,3,FALSE) -> 1B/DH | I29: =B29 -> 0.50874186 | J29: =VLOOKUP(G29,ADP!$B$1:$K$646,4,FALSE) -> 134.8 | K29: =_xlfn.CEILING.MATH(J29/12) -> 12 | T29: Michael Conforto
A30: Aranda, Jonathan | B30: 0.50485957 | E30: =LEFT(A30, FIND(",", A30) - 1) -> Aranda | F30: =TRIM(MID(A30, FIND(",", A30) + 1, LEN(A30))) -> Jonathan | G30: =F30 & " " & E30 -> Jonathan Aranda | H30: =VLOOKUP(G30,ADP!$B$1:$K$646,3,FALSE) -> 1B | I30: =B30 -> 0.50485957 | J30: =VLOOKUP(G30,ADP!$B$1:$K$646,4,FALSE) -> 190.7 | K30: =_xlfn.CEILING.MATH(J30/12) -> 16 | T30: Lane Thomas
A31: Anthony, Roman | B31: 0.49944854 | E31: =LEFT(A31, FIND(",", A31) - 1) -> Anthony | F31: =TRIM(MID(A31, FIND(",", A31) + 1, LEN(A31))) -> Roman | G31: =F31 & " " & E31 -> Roman Anthony | H31: =VLOOKUP(G31,ADP!$B$1:$K$646,3,FALSE) -> OF | I31: =B31 -> 0.49944854 | J31: =VLOOKUP(G31,ADP!$B$1:$K$646,4,FALSE) -> 54.2 | K31: =_xlfn.CEILING.MATH(J31/12) -> 5 | T31: Jo Adell
A32: Story, Trevor | B32: 0.49921 | E32: =LEFT(A32, FIND(",", A32) - 1) -> Story | F32: =TRIM(MID(A32, FIND(",", A32) + 1, LEN(A32))) -> Trevor | G32: =F32 & " " & E32 -> Trevor Story | H32: =VLOOKUP(G32,ADP!$B$1:$K$646,3,FALSE) -> SS | I32: =B32 -> 0.49921 | J32: =VLOOKUP(G32,ADP!$B$1:$K$646,4,FALSE) -> 106 | K32: =_xlfn.CEILING.MATH(J32/12) -> 9 | T32: Trevor Larnach
A33: Kurtz, Nick | B33: 0.4951985 | E33: =LEFT(A33, FIND(",", A33) - 1) -> Kurtz | F33: =TRIM(MID(A33, FIND(",", A33) + 1, LEN(A33))) -> Nick | G33: =F33 & " " & E33 -> Nick Kurtz | H33: =VLOOKUP(G33,ADP!$B$1:$K$646,3,FALSE) -> 1B | I33: =B33 -> 0.4951985 | J33: =VLOOKUP(G33,ADP!$B$1:$K$646,4,FALSE) -> 17.1 | K33: =_xlfn.CEILING.MATH(J33/12) -> 2 | T33: Corbin Carroll
A34: Adell, Jo | B34: 0.49494833 | E34: =LEFT(A34, FIND(",", A34) - 1) -> Adell | F34: =TRIM(MID(A34, FIND(",", A34) + 1, LEN(A34))) -> Jo | G34: =F34 & " " & E34 -> Jo Adell | H34: =VLOOKUP(G34,ADP!$B$1:$K$646,3,FALSE) -> OF | I34: =B34 -> 0.49494833 | J34: =VLOOKUP(G34,ADP!$B$1:$K$646,4,FALSE) -> 122.2 | K34: =_xlfn.CEILING.MATH(J34/12) -> 11 | T34: Heliot Ramos
A35: Baldwin, Brooks | B35: 0.49043992 | E35: =LEFT(A35, FIND(",", A35) - 1) -> Baldwin | F35: =TRIM(MID(A35, FIND(",", A35) + 1, LEN(A35))) -> Brooks | G35: =F35 & " " & E35 -> Brooks Baldwin | H35: =VLOOKUP(G35,ADP!$B$1:$K$646,3,FALSE) -> #N/A | I35: =B35 -> 0.49043992 | J35: =VLOOKUP(G35,ADP!$B$1:$K$646,4,FALSE) -> #N/A | K35: =_xlfn.CEILING.MATH(J35/12) -> #N/A | T35: Parker Meadows
A36: Triolo, Jared | B36: 0.4868623 | E36: =LEFT(A36, FIND(",", A36) - 1) -> Triolo | F36: =TRIM(MID(A36, FIND(",", A36) + 1, LEN(A36))) -> Jared | G36: =F36 & " " & E36 -> Jared Triolo | H36: =VLOOKUP(G36,ADP!$B$1:$K$646,3,FALSE) -> 1B/3B/SS | I36: =B36 -> 0.4868623 | J36: =VLOOKUP(G36,ADP!$B$1:$K$646,4,FALSE) -> 740.2 | K36: =_xlfn.CEILING.MATH(J36/12) -> 62 | T36: Dylan Crews
A37: Grichuk, Randal | B37: 0.4846786 | E37: =LEFT(A37, FIND(",", A37) - 1) -> Grichuk | F37: =TRIM(MID(A37, FIND(",", A37) + 1, LEN(A37))) -> Randal | G37: =F37 & " " & E37 -> Randal Grichuk | H37: =VLOOKUP(G37,ADP!$B$1:$K$646,3,FALSE) -> #N/A | I37: =B37 -> 0.4846786 | J37: =VLOOKUP(G37,ADP!$B$1:$K$646,4,FALSE) -> #N/A | K37: =_xlfn.CEILING.MATH(J37/12) -> #N/A
A38: Springer, George | B38: 0.47824115 | E38: =LEFT(A38, FIND(",", A38) - 1) -> Springer | F38: =TRIM(MID(A38, FIND(",", A38) + 1, LEN(A38))) -> George | G38: =F38 & " " & E38 -> George Springer | H38: =VLOOKUP(G38,ADP!$B$1:$K$646,3,FALSE) -> OF/DH | I38: =B38 -> 0.47824115 | J38: =VLOOKUP(G38,ADP!$B$1:$K$646,4,FALSE) -> 94.7 | K38: =_xlfn.CEILING.MATH(J38/12) -> 8
A39: Robert Jr., Luis | B39: 0.43693897 | E39: =LEFT(A39, FIND(",", A39) - 1) -> Robert Jr. | F39: =TRIM(MID(A39, FIND(",", A39) + 1, LEN(A39))) -> Luis | G39: =F39 & " " & E39 -> Luis Robert Jr. | H39: =VLOOKUP(G39,ADP!$B$1:$K$646,3,FALSE) -> OF | I39: =B39 -> 0.43693897 | J39: =VLOOKUP(G39,ADP!$B$1:$K$646,4,FALSE) -> 104.7 | K39: =_xlfn.CEILING.MATH(J39/12) -> 9
A40: Ramirez, Agustin | B40: 0.42875287 | E40: =LEFT(A40, FIND(",", A40) - 1) -> Ramirez | F40: =TRIM(MID(A40, FIND(",", A40) + 1, LEN(A40))) -> Agustin | G40: =F40 & " " & E40 -> Agustin Ramirez | H40: =VLOOKUP(G40,ADP!$B$1:$K$646,3,FALSE) -> C/DH | I40: =B40 -> 0.42875287 | J40: =VLOOKUP(G40,ADP!$B$1:$K$646,4,FALSE) -> 82.7 | K40: =_xlfn.CEILING.MATH(J40/12) -> 7
A41: Benson, Will | B41: 0.41992894 | E41: =LEFT(A41, FIND(",", A41) - 1) -> Benson | F41: =TRIM(MID(A41, FIND(",", A41) + 1, LEN(A41))) -> Will | G41: =F41 & " " & E41 -> Will Benson | H41: =VLOOKUP(G41,ADP!$B$1:$K$646,3,FALSE) -> #N/A | I41: =B41 -> 0.41992894 | J41: =VLOOKUP(G41,ADP!$B$1:$K$646,4,FALSE) -> #N/A | K41: =_xlfn.CEILING.MATH(J41/12) -> #N/A
A42: Duran, Jarren | B42: 0.4189566 | E42: =LEFT(A42, FIND(",", A42) - 1) -> Duran | F42: =TRIM(MID(A42, FIND(",", A42) + 1, LEN(A42))) -> Jarren | G42: =F42 & " " & E42 -> Jarren Duran | H42: =VLOOKUP(G42,ADP!$B$1:$K$646,3,FALSE) -> OF | I42: =B42 -> 0.4189566 | J42: =VLOOKUP(G42,ADP!$B$1:$K$646,4,FALSE) -> 72.6 | K42: =_xlfn.CEILING.MATH(J42/12) -> 7
...

Sheet Pitcher_Tiers
A1: last_name, first_name | B1: Sum(great_season_probability) | F1: Name | G1: Position | H1: Sum(great_season_probability) | I1: ADP | J1: Round
A2: Sanchez, Cristopher | B2: 0.834039 | D2: =LEFT(A2, FIND(",", A2) - 1) -> Sanchez | E2: =TRIM(MID(A2, FIND(",", A2) + 1, LEN(A2))) -> Cristopher | F2: =E2 & " " & D2 -> Cristopher Sanchez | G2: =VLOOKUP(F2,ADP!$B$1:$K$646,3,FALSE) -> SP | H2: =B2 -> 0.834039 | I2: =VLOOKUP(F2,ADP!$B$1:$K$1549,4,FALSE) -> 26.4 | J2: =_xlfn.CEILING.MATH(I2/12) -> 3
A3: Sale, Chris | B3: 0.8066467 | D3: =LEFT(A3, FIND(",", A3) - 1) -> Sale | E3: =TRIM(MID(A3, FIND(",", A3) + 1, LEN(A3))) -> Chris | F3: =E3 & " " & D3 -> Chris Sale | G3: =VLOOKUP(F3,ADP!$B$1:$K$646,3,FALSE) -> SP | H3: =B3 -> 0.8066467 | I3: =VLOOKUP(F3,ADP!$B$1:$K$1082,4,FALSE) -> 38.7 | J3: =_xlfn.CEILING.MATH(I3/12) -> 4
A4: Skubal, Tarik | B4: 0.7353988 | D4: =LEFT(A4, FIND(",", A4) - 1) -> Skubal | E4: =TRIM(MID(A4, FIND(",", A4) + 1, LEN(A4))) -> Tarik | F4: =E4 & " " & D4 -> Tarik Skubal | G4: =VLOOKUP(F4,ADP!$B$1:$K$646,3,FALSE) -> SP | H4: =B4 -> 0.7353988 | I4: =VLOOKUP(F4,ADP!$B$1:$K$1082,4,FALSE) -> 6.9 | J4: =_xlfn.CEILING.MATH(I4/12) -> 1
A5: Lodolo, Nick | B5: 0.7336966 | D5: =LEFT(A5, FIND(",", A5) - 1) -> Lodolo | E5: =TRIM(MID(A5, FIND(",", A5) + 1, LEN(A5))) -> Nick | F5: =E5 & " " & D5 -> Nick Lodolo | G5: =VLOOKUP(F5,ADP!$B$1:$K$646,3,FALSE) -> SP | H5: =B5 -> 0.7336966 | I5: =VLOOKUP(F5,ADP!$B$1:$K$1082,4,FALSE) -> 128.6 | J5: =_xlfn.CEILING.MATH(I5/12) -> 11
A6: Gilbert, Logan | B6: 0.6581922 | D6: =LEFT(A6, FIND(",", A6) - 1) -> Gilbert | E6: =TRIM(MID(A6, FIND(",", A6) + 1, LEN(A6))) -> Logan | F6: =E6 & " " & D6 -> Logan Gilbert | G6: =VLOOKUP(F6,ADP!$B$1:$K$646,3,FALSE) -> SP | H6: =B6 -> 0.6581922 | I6: =VLOOKUP(F6,ADP!$B$1:$K$1082,4,FALSE) -> 33.6 | J6: =_xlfn.CEILING.MATH(I6/12) -> 3
A7: Suarez, Ranger | B7: 0.6535916 | D7: =LEFT(A7, FIND(",", A7) - 1) -> Suarez | E7: =TRIM(MID(A7, FIND(",", A7) + 1, LEN(A7))) -> Ranger | F7: =E7 & " " & D7 -> Ranger Suarez | G7: =VLOOKUP(F7,ADP!$B$1:$K$646,3,FALSE) -> SP | H7: =B7 -> 0.6535916 | I7: =VLOOKUP(F7,ADP!$B$1:$K$1082,4,FALSE) -> 175.9 | J7: =_xlfn.CEILING.MATH(I7/12) -> 15
A8: Imanaga, Shota | B8: 0.6528158 | D8: =LEFT(A8, FIND(",", A8) - 1) -> Imanaga | E8: =TRIM(MID(A8, FIND(",", A8) + 1, LEN(A8))) -> Shota | F8: =E8 & " " & D8 -> Shota Imanaga | G8: =VLOOKUP(F8,ADP!$B$1:$K$646,3,FALSE) -> SP | H8: =B8 -> 0.6528158 | I8: =VLOOKUP(F8,ADP!$B$1:$K$1082,4,FALSE) -> 174.7 | J8: =_xlfn.CEILING.MATH(I8/12) -> 15
A9: deGrom, Jacob | B9: 0.62830323 | D9: =LEFT(A9, FIND(",", A9) - 1) -> deGrom | E9: =TRIM(MID(A9, FIND(",", A9) + 1, LEN(A9))) -> Jacob | F9: =E9 & " " & D9 -> Jacob deGrom | G9: =VLOOKUP(F9,ADP!$B$1:$K$646,3,FALSE) -> SP | H9: =B9 -> 0.62830323 | I9: =VLOOKUP(F9,ADP!$B$1:$K$1082,4,FALSE) -> 47.1 | J9: =_xlfn.CEILING.MATH(I9/12) -> 4
A10: Bubic, Kris | B10: 0.60481995 | D10: =LEFT(A10, FIND(",", A10) - 1) -> Bubic | E10: =TRIM(MID(A10, FIND(",", A10) + 1, LEN(A10))) -> Kris | F10: =E10 & " " & D10 -> Kris Bubic | G10: =VLOOKUP(F10,ADP!$B$1:$K$646,3,FALSE) -> SP | H10: =B10 -> 0.60481995 | I10: =VLOOKUP(F10,ADP!$B$1:$K$1082,4,FALSE) -> 205.6 | J10: =_xlfn.CEILING.MATH(I10/12) -> 18
A11: Yamamoto, Yoshinobu | B11: 0.5722887 | D11: =LEFT(A11, FIND(",", A11) - 1) -> Yamamoto | E11: =TRIM(MID(A11, FIND(",", A11) + 1, LEN(A11))) -> Yoshinobu | F11: =E11 & " " & D11 -> Yoshinobu Yamamoto | G11: =VLOOKUP(F11,ADP!$B$1:$K$646,3,FALSE) -> SP | H11: =B11 -> 0.5722887 | I11: =VLOOKUP(F11,ADP!$B$1:$K$1082,4,FALSE) -> 27.7 | J11: =_xlfn.CEILING.MATH(I11/12) -> 3
A12: Schwellenbach, Spencer | B12: 0.5298607 | D12: =LEFT(A12, FIND(",", A12) - 1) -> Schwellenbach | E12: =TRIM(MID(A12, FIND(",", A12) + 1, LEN(A12))) -> Spencer | F12: =E12 & " " & D12 -> Spencer Schwellenbach | G12: =VLOOKUP(F12,ADP!$B$1:$K$646,3,FALSE) -> SP | H12: =B12 -> 0.5298607 | I12: =VLOOKUP(F12,ADP!$B$1:$K$1082,4,FALSE) -> 421.6 | J12: =_xlfn.CEILING.MATH(I12/12) -> 36
A13: Woo, Bryan | B13: 0.52285117 | D13: =LEFT(A13, FIND(",", A13) - 1) -> Woo | E13: =TRIM(MID(A13, FIND(",", A13) + 1, LEN(A13))) -> Bryan | F13: =E13 & " " & D13 -> Bryan Woo | G13: =VLOOKUP(F13,ADP!$B$1:$K$646,3,FALSE) -> SP | H13: =B13 -> 0.52285117 | I13: =VLOOKUP(F13,ADP!$B$1:$K$1082,4,FALSE) -> 38.2 | J13: =_xlfn.CEILING.MATH(I13/12) -> 4
A14: Skenes, Paul | B14: 0.47025585 | D14: =LEFT(A14, FIND(",", A14) - 1) -> Skenes | E14: =TRIM(MID(A14, FIND(",", A14) + 1, LEN(A14))) -> Paul | F14: =E14 & " " & D14 -> Paul Skenes | G14: =VLOOKUP(F14,ADP!$B$1:$K$646,3,FALSE) -> SP | H14: =B14 -> 0.47025585 | I14: =VLOOKUP(F14,ADP!$B$1:$K$1082,4,FALSE) -> 10.2 | J14: =_xlfn.CEILING.MATH(I14/12) -> 1
... A28: Horton, Cade | B28: 0.25958872 | D28: =LEFT(A28, FIND(",", A28) - 1) -> Horton | E28: =TRIM(MID(A28, FIND(",", A28) + 1, LEN(A28))) -> Cade | F28: =E28 & " " & D28 -> Cade Horton | G28: =VLOOKUP(F28,ADP!$B$1:$K$646,3,FALSE) -> SP | H28: =B28 -> 0.25958872 | I28: =VLOOKUP(F28,ADP!$B$1:$K$1082,4,FALSE) -> 193 | J28: =_xlfn.CEILING.MATH(I28/12) -> 17
A29: Brown, Ben | B29: 0.252659 | D29: =LEFT(A29, FIND(",", A29) - 1) -> Brown | E29: =TRIM(MID(A29, FIND(",", A29) + 1, LEN(A29))) -> Ben | F29: =E29 & " " & D29 -> Ben Brown | G29: SP | H29: =B29 -> 0.252659 | I29: =VLOOKUP(F29,ADP!$B$1:$K$1082,4,FALSE) -> 0 | J29: =_xlfn.CEILING.MATH(I29/12) -> 0
A30: Peralta, Freddy | B30: 0.22768252 | D30: =LEFT(A30, FIND(",", A30) - 1) -> Peralta | E30: =TRIM(MID(A30, FIND(",", A30) + 1, LEN(A30))) -> Freddy | F30: =E30 & " " & D30 -> Freddy Peralta | G30: =VLOOKUP(F30,ADP!$B$1:$K$646,3,FALSE) -> SP | H30: =B30 -> 0.22768252 | I30: =VLOOKUP(F30,ADP!$B$1:$K$1082,4,FALSE) -> 58.4 | J30: =_xlfn.CEILING.MATH(I30/12) -> 5
A31: Boyd, Matthew | B31: 0.22314149 | D31: =LEFT(A31, FIND(",", A31) - 1) -> Boyd | E31: =TRIM(MID(A31, FIND(",", A31) + 1, LEN(A31))) -> Matthew | F31: =E31 & " " & D31 -> Matthew Boyd | G31: =VLOOKUP(F31,ADP!$B$1:$K$646,3,FALSE) -> SP | H31: =B31 -> 0.22314149 | I31: =VLOOKUP(F31,ADP!$B$1:$K$1082,4,FALSE) -> 233.3 | J31: =_xlfn.CEILING.MATH(I31/12) -> 20
A32: Gallen, Zac | B32: 0.21010177 | D32: =LEFT(A32, FIND(",", A32) - 1) -> Gallen | E32: =TRIM(MID(A32, FIND(",", A32) + 1, LEN(A32))) -> Zac | F32: =E32 & " " & D32 -> Zac Gallen | G32: =VLOOKUP(F32,ADP!$B$1:$K$646,3,FALSE) -> SP | H32: =B32 -> 0.21010177 | I32: =VLOOKUP(F32,ADP!$B$1:$K$1082,4,FALSE) -> 226 | J32: =_xlfn.CEILING.MATH(I32/12) -> 19
A33: Kelly, Merrill | B33: 0.20669363 | D33: =LEFT(A33, FIND(",", A33) - 1) -> Kelly | E33: =TRIM(MID(A33, FIND(",", A33) + 1, LEN(A33))) -> Merrill | F33: =E33 & " " & D33 -> Merrill Kelly | G33: =VLOOKUP(F33,ADP!$B$1:$K$646,3,FALSE) -> SP | H33: =B33 -> 0.20669363 | I33: =VLOOKUP(F33,ADP!$B$1:$K$1082,4,FALSE) -> 242.2 | J33: =_xlfn.CEILING.MATH(I33/12) -> 21
A34: Senga, Kodai | B34: 0.19448388 | D34: =LEFT(A34, FIND(",", A34) - 1) -> Senga | E34: =TRIM(MID(A34, FIND(",", A34) + 1, LEN(A34))) -> Kodai | F34: =E34 & " " & D34 -> Kodai Senga | G34: =VLOOKUP(F34,ADP!$B$1:$K$646,3,FALSE) -> SP | H34: =B34 -> 0.19448388 | I34: =VLOOKUP(F34,ADP!$B$1:$K$1082,4,FALSE) -> 255.5 | J34: =_xlfn.CEILING.MATH(I34/12) -> 22
A35: Soriano, Jose | B35: 0.19081157 | D35: =LEFT(A35, FIND(",", A35) - 1) -> Soriano | E35: =TRIM(MID(A35, FIND(",", A35) + 1, LEN(A35))) -> Jose | F35: =E35 & " " & D35 -> Jose Soriano | G35: =VLOOKUP(F35,ADP!$B$1:$K$646,3,FALSE) -> SP | H35: =B35 -> 0.19081157 | I35: =VLOOKUP(F35,ADP!$B$1:$K$1082,4,FALSE) -> 371.4 | J35: =_xlfn.CEILING.MATH(I35/12) -> 31
A36: Pepiot, Ryan | B36: 0.17540014 | D36: =LEFT(A36, FIND(",", A36) - 1) -> Pepiot | E36: =TRIM(MID(A36, FIND(",", A36) + 1, LEN(A36))) -> Ryan | F36: =E36 & " " & D36 -> Ryan Pepiot | G36: =VLOOKUP(F36,ADP!$B$1:$K$646,3,FALSE) -> SP | H36: =B36 -> 0.17540014 | I36: =VLOOKUP(F36,ADP!$B$1:$K$1082,4,FALSE) -> 132 | J36: =_xlfn.CEILING.MATH(I36/12) -> 11
A37: Kremer, Dean | B37: 0.16272049 | D37: =LEFT(A37, FIND(",", A37) - 1) -> Kremer | E37: =TRIM(MID(A37, FIND(",", A37) + 1, LEN(A37))) -> Dean | F37: =E37 & " " & D37 -> Dean Kremer | G37: =VLOOKUP(F37,ADP!$B$1:$K$646,3,FALSE) -> SP | H37: =B37 -> 0.16272049 | I37: =VLOOKUP(F37,ADP!$B$1:$K$1082,4,FALSE) -> 0 | J37: =_xlfn.CEILING.MATH(I37/12) -> 0
A38: Mize, Casey | B38: 0.15414311 | D38: =LEFT(A38, FIND(",", A38) - 1) -> Mize | E38: =TRIM(MID(A38, FIND(",", A38) + 1, LEN(A38))) -> Casey | F38: =E38 & " " & D38 -> Casey Mize | G38: =VLOOKUP(F38,ADP!$B$1:$K$646,3,FALSE) -> SP | H38: =B38 -> 0.15414311 | I38: =VLOOKUP(F38,ADP!$B$1:$K$1082,4,FALSE) -> 279.2 | J38: =_xlfn.CEILING.MATH(I38/12) -> 24
A39: Holmes, Grant | B39: 0.15399468 | D39: =LEFT(A39, FIND(",", A39) - 1) -> Holmes | E39: =TRIM(MID(A39, FIND(",", A39) + 1, LEN(A39))) -> Grant | F39: =E39 & " " & D39 -> Grant Holmes | G39: =VLOOKUP(F39,ADP!$B$1:$K$646,3,FALSE) -> SP | H39: =B39 -> 0.15399468 | I39: =VLOOKUP(F39,ADP!$B$1:$K$1082,4,FALSE) -> 546.8 | J39: =_xlfn.CEILING.MATH(I39/12) -> 46
A40: Smith, Shane | B40: 0.14698155 | D40: =LEFT(A40, FIND(",", A40) - 1) -> Smith | E40: =TRIM(MID(A40, FIND(",", A40) + 1, LEN(A40))) -> Shane | F40: =E40 & " " & D40 -> Shane Smith | G40: =VLOOKUP(F40,ADP!$B$1:$K$646,3,FALSE) -> SP | H40: =B40 -> 0.14698155 | I40: =VLOOKUP(F40,ADP!$B$1:$K$1082,4,FALSE) -> 253.4 | J40: =_xlfn.CEILING.MATH(I40/12) -> 22
A41: Verlander, Justin | B41: 0.14428885 | D41: =LEFT(A41, FIND(",", A41) - 1) -> Verlander | E41: =TRIM(MID(A41, FIND(",", A41) + 1, LEN(A41))) -> Justin | F41: =E41 & " " & D41 -> Justin Verlander | G41: =VLOOKUP(F41,ADP!$B$1:$K$646,3,FALSE) -> SP | H41: =B41 -> 0.14428885 | I41: =VLOOKUP(F41,ADP!$B$1:$K$1082,4,FALSE) -> 708.9 | J41: =_xlfn.CEILING.MATH(I41/12) -> 60
... A45: Cameron, Noah | B45: 0.10356321 | D45: =LEFT(A45, FIND(",", A45) - 1) -> Cameron | E45: =TRIM(MID(A45, FIND(",", A45) + 1, LEN(A45))) -> Noah | F45: =E45 & " " & D45 -> Noah Cameron | G45: =VLOOKUP(F45,ADP!$B$1:$K$646,3,FALSE) -> SP | H45: =B45 -> 0.10356321 | I45: =VLOOKUP(F45,ADP!$B$1:$K$1082,4,FALSE) -> 266.7 | J45: =_xlfn.CEILING.MATH(I45/12) -> 23

Sheet ADP
A1: # | B1: Name | C1: Team | D1: POS | E1: ADP | F1: Roster% | G1: Start% | H1: PA | I1: IP | J1: Dollars | K1: Card | L1: Card
A2: 1 | B2: Shohei Ohtani | C2: LAD | D2: DH | E2: 1.3 | F2: 1 | G2: 1 | H2: 727 | J2: 42.5
A3: 2 | B3: Shohei Ohtani | C3: LAD | D3: SP | E3: 1.3 | F3: 1 | G3: 1 | I3: 47 | J3: 1
A4: 3 | B4: Aaron Judge | C4: NYY | D4: OF/DH | E4: 1.9 | F4: 1 | G4: 1 | H4: 679 | J4: 47.6
A5: 4 | B5: Bobby Witt Jr. | C5: KCR | D5: SS | E5: 2.9 | F5: 1 | G5: 1 | H5: 687 | J5: 30.6
A6: 5 | B6: Juan Soto | C6: NYM | D6: OF | E6: 4.5 | F6: 1 | G6: 1 | H6: 715 | J6: 37.6
A7: 6 | B7: Jose Ramirez | C7: CLE | D7: 3B/DH | E7: 5.8 | F7: 1 | G7: 1 | H7: 673 | J7: 32.3
A8: 7 | B8: Ronald Acuna Jr. | C8: ATL | D8: OF | E8: 6.3 | F8: 1 | G8: 1 | H8: 412 | J8: 7.6
A9: 8 | B9: Tarik Skubal | C9: DET | D9: SP | E9: 6.9 | F9: 1 | G9: 1 | I9: 195 | J9: 35.5
A10: 9 | B10: Elly De La Cruz | C10: CIN | D10: SS | E10: 8.5 | F10: 1 | G10: 1 | H10: 699 | J10: 24.8
A11: 10 | B11: Paul Skenes | C11: PIT | D11: SP | E11: 10.2 | F11: 1 | G11: 1 | I11: 187.1 | J11: 30.6
A12: 11 | B12: Julio Rodriguez | C12: SEA | D12: OF | E12: 10.6 | F12: 1 | G12: 1 | H12: 710 | J12: 28.8
A13: 12 | B13: Garrett Crochet | C13: BOS | D13: SP | E13: 11.4 | F13: 1 | G13: 1 | I13: 205 | J13: 32.8
A14: 13 | B14: Corbin Carroll | C14: ARI | D14: OF | E14: 12.2 | F14: 1 | G14: 0.86 | H14: 642 | J14: 26.1
A15: 14 | B15: Gunnar Henderson | C15: BAL | D15: SS | E15: 12.8 | F15: 1 | G15: 1 | H15: 651 | J15: 17.2
A16: 15 | B16: Kyle Tucker | C16: LAD | D16: OF | E16: 14.4 | F16: 1 | G16: 1 | H16: 597 | J16: 18.1
A17: 16 | B17: Fernando Tatis Jr. | C17: SDP | D17: OF | E17: 14.8 | F17: 1 | G17: 1 | H17: 691 | J17: 24.2
A18: 17 | B18: Junior Caminero | C18: TBR | D18: 3B | E18: 16.3 | F18: 1 | G18: 1 | H18: 653 | J18: 26
A19: 18 | B19: Nick Kurtz | C19: ATH | D19: 1B | E19: 17.1 | F19: 1 | G19: 1 | H19: 489 | J19: 20.1
A20: 19 | B20: Vladimir Guerrero Jr. | C20: TOR | D20: 1B/DH | E20: 18 | F20: 1 | G20: 0.98 | H20: 680 | J20: 19.4
A21: 20 | B21: Cal Raleigh | C21: SEA | D21: C/DH | E21: 18.5 | F21: 1 | G21: 1 | H21: 705 | J21: 44.5
A22: 21 | B22: Jackson Chourio | C22: MIL | D22: OF | E22: 19.6 | F22: 1 | G22: 1 | H22: 589 | J22: 17.6
A23: 22 | B23: Jazz Chisholm Jr. | C23: NYY | D23: 2B/3B | E23: 20.9 | F23: 1 | G23: 1 | H23: 531 | J23: 18.1
A24: 23 | B24: Francisco Lindor | C24: NYM | D24: SS | E24: 23.4 | F24: 1 | G24: 0.82 | H24: 732 | J24: 28.9
A25: 24 | B25: Kyle Schwarber | C25: PHI | D25: DH | E25: 24.5 | F25: 1 | G25: 1 | H25: 724 | J25: 32.4
A26: 25 | B26: Pete Alonso | C26: BAL | D26: 1B | E26: 25 | F26: 1 | G26: 1 | H26: 709 | J26: 24.9
A27: 26 | B27: Cristopher Sanchez | C27: PHI | D27: SP | E27: 26.4 | F27: 1 | G27: 1 | I27: 202 | J27: 25.4
A28: 27 | B28: Zach Neto | C28: LAA | D28: SS | E28: 26.4 | F28: 1 | G28: 1 | H28: 554 | J28: 14.9
A29: 28 | B29: Yoshinobu Yamamoto | C29: LAD | D29: SP | E29: 27.7 | F29: 1 | G29: 1 | I29: 173.1 | J29: 25.4
A30: 29 | B30: Trea Turner | C30: PHI | D30: SS | E30: 27.8 | F30: 1 | G30: 1 | H30: 639 | J30: 24.7
A31: 30 | B31: Mason Miller | C31: SDP | D31: RP | E31: 29 | F31: 1 | G31: 0.96 | I31: 61.1 | J31: 4.5
A32: 31 | B32: Pete Crow-Armstrong | C32: CHC | D32: OF | E32: 31 | F32: 1 | G32: 1 | H32: 647 | J32: 24.2
A33: 32 | B33: Ketel Marte | C33: ARI | D33: 2B/DH | E33: 32.6 | F33: 1 | G33: 1 | H33: 556 | J33: 15.6
A34: 33 | B34: James Wood | C34: WSN | D34: OF/DH | E34: 33 | F34: 1 | G34: 1 | H34: 689 | J34: 19.3
A35: 34 | B35: Edwin Díaz | C35: LAD | D35: RP | E35: 33.1 | F35: 1 | G35: 0.98 | I35: 66 | J35: 13.1
A36: 35 | B36: Logan Gilbert | C36: SEA | D36: SP | E36: 33.6 | F36: 1 | G36: 1 | I36: 131 | J36: 11.3
A37: 36 | B37: Yordan Alvarez | C37: HOU | D37: DH | E37: 35.1 | F37: 1 | G37: 1 | H37: 199 | J37: -13.4
A38: 37 | B38: Hunter Brown | C38: HOU | D38: SP | E38: 37.3 | F38: 1 | G38: 1 | I38: 185 | J38: 25.5
A39: 38 | B39: Bryan Woo | C39: SEA | D39: SP | E39: 38.2 | F39: 1 | G39: 1 | I39: 186.1 | J39: 27.3
A40: 39 | B40: Chris Sale | C40: ATL | D40: SP | E40: 38.7 | F40: 1 | G40: 1 | I40: 125.1 | J40: 14.6
...
