Workbook

Sheet Ideal_Lineup
A1: Round | B1: First Pick | C1: Back Up | D1: Back Up 2
A2: 1 | B2: Aaron Judge | C2: Shohei Ohtani | D2: Juan Soto
A3: 2 | B3: Yordan Alvarez | C3: Rafael Devers | D3: Freddie Freeman
A4: 3 | B4: Ronald Acuna Jr | C4: Jackson Merrill | D4: Garrett Crochet | I4: Ideal Round | J4: High Round | K4: Low Round | L4: Target | M4: Reach | N4: Fallback | O4: Player Rater
A5: 4 | B5: Corey Seager | C5: Kyle Schwarber | D5: Wyatt Langford | H5: c | I5: 7 | J5: 6 | K5: 7 | L5: Salvador Perez | M5: William Contreras | N5: Wilson Contreras | O5: 16.6
A6: 5 | B6: Christian Walker | C6: George Kirby | D6: Brent Rooker Jr | H6: 1b | I6: 6 | J6: 2 | K6: 16 | L6: Christian Walker | M6: Vlad Guerrero Jr/Matt Olson | N6: Yandy Diaz | O6: 13.8
A7: 6 | B7: Salvador Perez | C7: Jordan Westburg | D7: Framber Valdez | H7: 2b | I7: 8 | J7: 7 | K7: 19 | L7: Jordan Westburg/Marcus Semien | M7: Jordan Westburg | N7: Bryson Stott/Brandon Lowe
A8: 7 | B8: Tyler Glasnow | C8: Shoto Imanaga | D8: Junior Caminero | H8: ss | I8: 4 | J8: 3 | K8: 15 | L8: Corey Seager | M8: Corey Seager | N8: Ezequiel Tovar/Bryson Stott/Masyn Winn
A9: 8 | B9: Matt McLain | C9: Bailey Ober | D9: Cal Raleigh | H9: 3b | I9: 3 | J9: 2 | K9: 10 | L9: Rafael Devers/Austin Riley | M9: Jose Ramirez | N9: Matt Chapman
A10: 9 | B10: Sonny Gray | C10: Max Fried | D10: Christian Yelich | H10: of | I10: 1 | J10: 1 | K10: 2 | L10: Juan Soto | M10: Aaron Judge | N10: Yordan Alvarez/Ronald Acuna Jr
A11: 10 | B11: Luis Garcia Jr | C11: Mike Trout | D11: Justin Steele | H11: of | I11: 2 | J11: 2 | K11: 4 | L11: Ronald Acuna/Jackson Merrill | M11: Yordan Alvarez | N11: Michael Harris/James Wood
A12: 11 | B12: Justin Steele | C12: Spencer Strider | D12: Jared Jones | H12: of | I12: 11 | J12: 4 | K12: 13 | L12: Mike Trout | M12: Michael Harris Jr | N12: Pete Crow-Armstrong
A13: 12 | B13: Pete Crow-Armstrong | C13: Matt Chapman | D13: Bryan Woo | H13: util | I13: 9 | J13: 5 | K13: 11 | L13: Anthony Santander | M13: Brent Rooker | N13: Matt Chapman
A14: 13 | B14: Reynaldo Lopez | C14: Pete Crow-Armstrong | D14: Cristoper Sanchez | H14: util | I14: 13 | J14: 11 | K14: 20 | L14: Pete Crow-Armstrong | M14: Matt Chapman | N14: Byron Buxton
A15: 14 | B15: Nathan Eovaldi | C15: Ryan Pepiot | D15: Yusei Kikuchi | H15: sp | I15: 5 | J15: 4 | K15: 8 | L15: George Kirby | M15: Blake Snell/Garrett Crochet | N15: Roki Sasaki/Hunter Greene
A16: 15 | B16: Yusei Kikuchi | C16: Taj Bradley | D16: Luis Gil | H16: sp | I16: 10 | J16: 9 | K16: 12 | L16: Justin Steele | M16: Hunter Greene/Sonny Gray | N16: Bryan Woo
A17: 16 | B17: Jordan Romano | C17: Taj Bradley | D17: Jackson Jobe | H17: rp | I17: 15 | J17: 12 | K17: 19 | L17: Kirby Yates | M17: Jeff Hoffman | N17: Griffin Jax
A18: 17 | B18: Yandy Diaz | C18: Nick Martinez | D18: Lane Thomas | H18: rp | I18: 18 | J18: 15 | K18: 20 | L18: Griffin Jax | M18: Kirby Yates | N18: Tommy Kahnle/Jason Adam/Griffin Jax
... A25: 24 | B25: Nick Lodolo | C25: Sam Hilliard | D25: Evan Phillips | H25: p | I25: 21 | J25: 19 | K25: 21 | L25: Grant Holmes | M25: Nick Martinez/Taj Bradley | N25: Ronel Blanco
H26: p | I26: 22 | J26: 20 | K26: 22 | L26: Jeremiah Estrada | M26: Grant Holmes | N26: Michael Wacha
H27: p | I27: 23 | J27: 21 | K27: 23 | L27: Dennis Santana | M27: Jeremiah Estrada | N27: Reed Garrett/Dedniel Nunez/Dennis Santana
L29: Also consider | M29: Luisangel Acuna, Roman Anthony, Jac Caglione
A31: Name | B31: Position | C31: Sum(great_season_probability) | D31: ADP | E31: Round | F31: BABIP_Expectation_Batter | G31: BABIP_Expectation_Pitcher
A32: Shohei Ohtani | B32: DH | C32: 0.92943645 | D32: 1.5 | E32: 1 | F32: Same | G32: #N/A
A33: Aaron Judge | B33: OF/DH | C33: 0.9162953 | D33: 3.4 | E33: 1 | F33: Regression | G33: #N/A
A34: Vladimir Guerrero Jr. | B34: 1B/DH | C34: 0.9117822 | D34: 14.4 | E34: 2 | F34: Regression | G34: #N/A
A35: Fernando Tatis Jr. | B35: OF | C35: 0.9117414 | D35: 10.6 | E35: 1 | F35: Regression | G35: #N/A
A36: Reed Garrett | B36: RP | C36: 0.9159347 | D36: #N/A | E36: #N/A | F36: #N/A | G36: #N/A
A37: Juan Soto | B37: OF | C37: 0.86973935 | D37: 7.8 | E37: 1 | F37: Regression | G37: #N/A
A38: Dedniel Nunez | B38: RP | C38: 0.898492 | D38: #N/A | E38: #N/A | F38: #N/A | G38: #N/A
A39: Yordan Alvarez | B39: OF/DH | C39: 0.8654861 | D39: 17.6 | E39: 2 | F39: Same | G39: #N/A
A40: Jake Cousins | B40: RP | C40: 0.8984478 | D40: #N/A | E40: #N/A | F40: #N/A | G40: #N/A
A41: Rafael Devers | B41: 3B | C41: 0.8580056 | D41: 34.8 | E41: 3 | F41: Same | G41: #N/A
A42: Tommy Kahnle | B42: RP | C42: 0.89481205 | D42: 240 | E42: 20 | F42: #N/A | G42: #N/A
A43: Griffin Jax | B43: RP | C43: 0.8824934 | D43: 239 | E43: 20 | F43: #N/A | G43: #N/A
A44: Austin Riley | B44: 3B | C44: 0.8494359 | D44: 29.5 | E44: 3 | F44: Same | G44: #N/A
A45: Ian Hamilton | B45: RP | C45: 0.8822293 | D45: #N/A | E45: #N/A | F45: #N/A | G45: #N/A
A46: Bobby Witt Jr. | B46: SS | C46: 0.84757924 | D46: 1.6 | E46: 1 | F46: Regression | G46: #N/A
A47: Jerar Encarnacion | B47: 1B/OF/DH | C47: 0.8275798 | D47: #N/A | E47: #N/A | F47: #N/A | G47: #N/A
A48: Ryan Helsley | B48: RP | C48: 0.87516254 | D48: 50.7 | E48: 5 | F48: #N/A | G48: #N/A
...

Sheet Batter_Tiers
A1: Tier 1 | B1: Improve or Regress | C1: Great Season Prob | E1: last_name, first_name | F1: Sum(great_season_probability) | K1: Name | L1: Sum(great_season_probability) | M1: ADP | N1: Round | Q1: Watch List | R1: C | S1: 1B | T1: 2B | U1: 3B | V1: SS | W1: OF | X1: Util | Y1: SP | Z1: RP
A2: Aaron Judge | B2: Regress | C2: =VLOOKUP(A2,$K$1:$L$102,2,FALSE) -> 0.9162953 | E2: Ohtani, Shohei | F2: 0.92943645 | I2: {=_xlfn.TEXTSPLIT(E2,",")} -> Ohtani | J2: Shohei | K2: =REPLACE(_xlfn.CONCAT(J2," ",I2), 1, 1,"") -> Shohei Ohtani | L2: 0.92943645 | M2: =VLOOKUP(K2,ADP!$B$1:$N$646,4,FALSE) -> 1.5 | N2: =_xlfn.CEILING.MATH(M2/12) -> 1 | R2: Salvador Perez | S2: Christian Walker | T2: Jordan Westburg | U2: Rafael Devers | V2: Bobby Witt Jr. | W2: Aaron Judge | X2: Shohei Ohtani
E3: Judge, Aaron | F3: 0.9162953 | I3: {=_xlfn.TEXTSPLIT(E3,",")} -> Judge | J3: Aaron | K3: =REPLACE(_xlfn.CONCAT(J3," ",I3), 1, 1,"") -> Aaron Judge | L3: 0.9162953 | M3: =VLOOKUP(K3,ADP!$B$1:$N$646,4,FALSE) -> 3.4 | N3: =_xlfn.CEILING.MATH(M3/12) -> 1 | R3: William Contreras | S3: Matt Olson | T3: Ketel Marte | U3: Austin Riley | V3: Corey Seager | W3: Vladimir Guerrero Jr.
A4: Tier 2 | E4: Guerrero Jr., Vladimir | F4: 0.9117822 | I4: {=_xlfn.TEXTSPLIT(E4,",")} -> Guerrero Jr. | J4: Vladimir | K4: =REPLACE(_xlfn.CONCAT(J4," ",I4), 1, 1,"") -> Vladimir Guerrero Jr. | L4: 0.9117822 | M4: =VLOOKUP(K4,ADP!$B$1:$N$646,4,FALSE) -> 14.4 | N4: =_xlfn.CEILING.MATH(M4/12) -> 2 | R4: Wilson Contreras | S4: Tyler Soderstrom | T4: Brandon Lowe | U4: Matt Chapman | V4: Oneil Cruz | W4: Fernando Tatis Jr.
A5: Shohei Ohtani | B5: Same | C5: =VLOOKUP(A5,$K$1:$L$102,2,FALSE) -> 0.92943645 | E5: Tatis Jr., Fernando | F5: 0.9117414 | I5: {=_xlfn.TEXTSPLIT(E5,",")} -> Tatis Jr. | J5: Fernando | K5: =REPLACE(_xlfn.CONCAT(J5," ",I5), 1, 1,"") -> Fernando Tatis Jr. | L5: 0.9117414 | M5: =VLOOKUP(K5,ADP!$B$1:$N$646,4,FALSE) -> 10.6 | N5: =_xlfn.CEILING.MATH(M5/12) -> 1 | S5: Bryce Harper | T5: Marcus Semien | U5: Gunnar Henderson | V5: Francisco Lindor | W5: Juan Soto
E6: Soto, Juan | F6: 0.86973935 | I6: {=_xlfn.TEXTSPLIT(E6,",")} -> Soto | J6: Juan | K6: =REPLACE(_xlfn.CONCAT(J6," ",I6), 1, 1,"") -> Juan Soto | L6: 0.86973935 | M6: =VLOOKUP(K6,ADP!$B$1:$N$646,4,FALSE) -> 7.8 | N6: =_xlfn.CEILING.MATH(M6/12) -> 1 | S6: Pete Alonso | T6: Bryson Stott | U6: Manny Machado | V6: Ezequiel Tovar | W6: Yordan Alvarez
A7: Tier 3 | E7: Alvarez, Yordan | F7: 0.8654861 | I7: {=_xlfn.TEXTSPLIT(E7,",")} -> Alvarez | J7: Yordan | K7: =REPLACE(_xlfn.CONCAT(J7," ",I7), 1, 1,"") -> Yordan Alvarez | L7: 0.8654861 | M7: =VLOOKUP(K7,ADP!$B$1:$N$646,4,FALSE) -> 17.6 | N7: =_xlfn.CEILING.MATH(M7/12) -> 2 | S7: Luke Raley | T7: Mookie Betts | U7: Miguel Vargas | V7: Elly De La Cruz | W7: Mike Trout
A8: Yordan Alvarez | B8: Same | C8: =VLOOKUP(A8,$K$1:$L$102,2,FALSE) -> 0.8654861 | E8: Devers, Rafael | F8: 0.8580056 | I8: {=_xlfn.TEXTSPLIT(E8,",")} -> Devers | J8: Rafael | K8: =REPLACE(_xlfn.CONCAT(J8," ",I8), 1, 1,"") -> Rafael Devers | L8: 0.8580056 | M8: =VLOOKUP(K8,ADP!$B$1:$N$646,4,FALSE) -> 34.8 | N8: =_xlfn.CEILING.MATH(M8/12) -> 3 | S8: Yandy Díaz | U8: José Ramírez | V8: Masyn Winn | W8: Giancarlo Stanton
A9: Juan Soto | B9: Regress | C9: =VLOOKUP(A9,$K$1:$L$102,2,FALSE) -> 0.86973935 | E9: Riley, Austin | F9: 0.8494359 | I9: {=_xlfn.TEXTSPLIT(E9,",")} -> Riley | J9: Austin | K9: =REPLACE(_xlfn.CONCAT(J9," ",I9), 1, 1,"") -> Austin Riley | L9: 0.8494359 | M9: =VLOOKUP(K9,ADP!$B$1:$N$646,4,FALSE) -> 29.5 | N9: =_xlfn.CEILING.MATH(M9/12) -> 3 | V9: =REPLACE(_xlfn.CONCAT(U9," ",T9), 1, 1,"") | W9: Jackson Merrill
E10: Witt Jr., Bobby | F10: 0.84757924 | I10: {=_xlfn.TEXTSPLIT(E10,",")} -> Witt Jr. | J10: Bobby | K10: =REPLACE(_xlfn.CONCAT(J10," ",I10), 1, 1,"") -> Bobby Witt Jr. | L10: 0.84757924 | M10: =VLOOKUP(K10,ADP!$B$1:$N$646,4,FALSE) -> 1.6 | N10: =_xlfn.CEILING.MATH(M10/12) -> 1 | W10: Matt Olson
A11: Tier 4 | E11: Encarnacion, Jerar | F11: 0.8275798 | I11: {=_xlfn.TEXTSPLIT(E11,",")} -> Encarnacion | J11: Jerar | K11: =REPLACE(_xlfn.CONCAT(J11," ",I11), 1, 1,"") -> Jerar Encarnacion | L11: 0.8275798 | M11: =VLOOKUP(K11,ADP!$B$1:$N$646,4,FALSE) -> #N/A | N11: =_xlfn.CEILING.MATH(M11/12) -> #N/A | W11: Michael Harris II
A12: Bobby Witt Jr. | B12: Regress | C12: =VLOOKUP(A12,$K$1:$L$102,2,FALSE) -> 0.84757924 | E12: Seager, Corey | F12: 0.75745606 | I12: {=_xlfn.TEXTSPLIT(E12,",")} -> Seager | J12: Corey | K12: =REPLACE(_xlfn.CONCAT(J12," ",I12), 1, 1,"") -> Corey Seager | L12: 0.75745606 | M12: =VLOOKUP(K12,ADP!$B$1:$N$646,4,FALSE) -> 49.2 | N12: =_xlfn.CEILING.MATH(M12/12) -> 5 | W12: Kyle Tucker
A13: Brent Rooker | B13: Regress | C13: =VLOOKUP(A13,$K$1:$L$102,2,FALSE) -> 0.18024568 | E13: Chapman, Matt | F13: 0.7129335 | I13: {=_xlfn.TEXTSPLIT(E13,",")} -> Chapman | J13: Matt | K13: =REPLACE(_xlfn.CONCAT(J13," ",I13), 1, 1,"") -> Matt Chapman | L13: 0.7129335 | M13: =VLOOKUP(K13,ADP!$B$1:$N$646,4,FALSE) -> 130.2 | N13: =_xlfn.CEILING.MATH(M13/12) -> 11 | W13: Jackson Chourio
A14: Bryce Harper | B14: Same | C14: =VLOOKUP(A14,$K$1:$L$102,2,FALSE) -> 0.1963839 | E14: Henderson, Gunnar | F14: 0.65990394 | I14: {=_xlfn.TEXTSPLIT(E14,",")} -> Henderson | J14: Gunnar | K14: =REPLACE(_xlfn.CONCAT(J14," ",I14), 1, 1,"") -> Gunnar Henderson | L14: 0.65990394 | M14: =VLOOKUP(K14,ADP!$B$1:$N$646,4,FALSE) -> 6.1 | N14: =_xlfn.CEILING.MATH(M14/12) -> 1 | W14: Matt Wallner
A15: Freddie Freeman | B15: Improve | C15: =VLOOKUP(A15,$K$1:$L$102,2,FALSE) -> #N/A | E15: Trout, Mike | F15: 0.6587786 | I15: {=_xlfn.TEXTSPLIT(E15,",")} -> Trout | J15: Mike | K15: =REPLACE(_xlfn.CONCAT(J15," ",I15), 1, 1,"") -> Mike Trout | L15: 0.6587786 | M15: =VLOOKUP(K15,ADP!$B$1:$N$646,4,FALSE) -> #N/A | N15: =_xlfn.CEILING.MATH(M15/12) -> #N/A | W15: Julio Rodríguez
A16: Gunnar Henderson | B16: Same | C16: =VLOOKUP(A16,$K$1:$L$102,2,FALSE) -> 0.65990394 | E16: Stanton, Giancarlo | F16: 0.6508743 | I16: {=_xlfn.TEXTSPLIT(E16,",")} -> Stanton | J16: Giancarlo | K16: =REPLACE(_xlfn.CONCAT(J16," ",I16), 1, 1,"") -> Giancarlo Stanton | L16: 0.6508743 | M16: =VLOOKUP(K16,ADP!$B$1:$N$646,4,FALSE) -> 381.6 | N16: =_xlfn.CEILING.MATH(M16/12) -> 32 | W16: Leody Taveras
A17: Jose Altuve | B17: Same | C17: =VLOOKUP(A17,$K$1:$L$102,2,FALSE) -> #N/A | E17: Merrill, Jackson | F17: 0.60806304 | I17: {=_xlfn.TEXTSPLIT(E17,",")} -> Merrill | J17: Jackson | K17: =REPLACE(_xlfn.CONCAT(J17," ",I17), 1, 1,"") -> Jackson Merrill | L17: 0.60806304 | M17: =VLOOKUP(K17,ADP!$B$1:$N$646,4,FALSE) -> 25.6 | N17: =_xlfn.CEILING.MATH(M17/12) -> 3 | W17: Jesús Sánchez
A18: Kyle Tucker | B18: Same | C18: =VLOOKUP(A18,$K$1:$L$102,2,FALSE) -> 0.3784005 | E18: Walker, Christian | F18: 0.54935026 | I18: {=_xlfn.TEXTSPLIT(E18,",")} -> Walker | J18: Christian | K18: =REPLACE(_xlfn.CONCAT(J18," ",I18), 1, 1,"") -> Christian Walker | L18: 0.54935026 | M18: =VLOOKUP(K18,ADP!$B$1:$N$646,4,FALSE) -> 95.3 | N18: =_xlfn.CEILING.MATH(M18/12) -> 8 | W18: Oneil Cruz
A19: Matt Wallner | B19: Regress | C19: =VLOOKUP(A19,$K$1:$L$102,2,FALSE) -> 0.36942366 | E19: Westburg, Jordan | F19: 0.5130863 | I19: {=_xlfn.TEXTSPLIT(E19,",")} -> Westburg | J19: Jordan | K19: =REPLACE(_xlfn.CONCAT(J19," ",I19), 1, 1,"") -> Jordan Westburg | L19: 0.5130863 | M19: =VLOOKUP(K19,ADP!$B$1:$N$646,4,FALSE) -> 90.5 | N19: =_xlfn.CEILING.MATH(M19/12) -> 8 | W19: Anthony Santander
A20: Mookie Betts | B20: Same | C20: =VLOOKUP(A20,$K$1:$L$102,2,FALSE) -> 0.10150944 | E20: Olson, Matt | F20: 0.4927301 | I20: {=_xlfn.TEXTSPLIT(E20,",")} -> Olson | J20: Matt | K20: =REPLACE(_xlfn.CONCAT(J20," ",I20), 1, 1,"") -> Matt Olson | L20: 0.4927301 | M20: =VLOOKUP(K20,ADP!$B$1:$N$646,4,FALSE) -> 38.7 | N20: =_xlfn.CEILING.MATH(M20/12) -> 4 | W20: Wyatt Langford
A21: Ronald Acuna Jr | B21: Same | C21: =VLOOKUP(A21,$K$1:$L$102,2,FALSE) -> #N/A | E21: Buxton, Byron | F21: 0.48360714 | I21: {=_xlfn.TEXTSPLIT(E21,",")} -> Buxton | J21: Byron | K21: =REPLACE(_xlfn.CONCAT(J21," ",I21), 1, 1,"") -> Byron Buxton | L21: 0.48360714 | M21: =VLOOKUP(K21,ADP!$B$1:$N$646,4,FALSE) -> 240.7 | N21: =_xlfn.CEILING.MATH(M21/12) -> 21 | W21: Kyle Schwarber
E22: Crow-Armstrong, Pete | F22: 0.48242712 | I22: {=_xlfn.TEXTSPLIT(E22,",")} -> Crow-Armstrong | J22: Pete | K22: =REPLACE(_xlfn.CONCAT(J22," ",I22), 1, 1,"") -> Pete Crow-Armstrong | L22: 0.48242712 | M22: =VLOOKUP(K22,ADP!$B$1:$N$646,4,FALSE) -> 138.7 | N22: =_xlfn.CEILING.MATH(M22/12) -> 12 | W22: Christian Yelich
A23: Tier 5 | E23: Marte, Ketel | F23: 0.47614032 | I23: {=_xlfn.TEXTSPLIT(E23,",")} -> Marte | J23: Ketel | K23: =REPLACE(_xlfn.CONCAT(J23," ",I23), 1, 1,"") -> Ketel Marte | L23: 0.47614032 | M23: =VLOOKUP(K23,ADP!$B$1:$N$646,4,FALSE) -> 32.4 | N23: =_xlfn.CEILING.MATH(M23/12) -> 3 | W23: Lars Nootbaar
A24: Byron Buxton | B24: Regress | C24: =VLOOKUP(A24,$K$1:$L$102,2,FALSE) -> 0.48360714 | E24: Gonzalez, Romy | F24: 0.38101044 | I24: {=_xlfn.TEXTSPLIT(E24,",")} -> Gonzalez | J24: Romy | K24: =REPLACE(_xlfn.CONCAT(J24," ",I24), 1, 1,"") -> Romy Gonzalez | L24: 0.38101044 | M24: =VLOOKUP(K24,ADP!$B$1:$N$646,4,FALSE) -> 645.8 | N24: =_xlfn.CEILING.MATH(M24/12) -> 54 | W24: Sam Hilliard
A25: Corbin Carroll | B25: Improve | C25: =VLOOKUP(A25,$K$1:$L$102,2,FALSE) -> 0.12744358 | E25: Harris II, Michael | F25: 0.3799269 | I25: {=_xlfn.TEXTSPLIT(E25,",")} -> Harris II | J25: Michael | K25: =REPLACE(_xlfn.CONCAT(J25," ",I25), 1, 1,"") -> Michael Harris II | L25: 0.3799269 | M25: =VLOOKUP(K25,ADP!$B$1:$N$646,4,FALSE) -> 37.9 | N25: =_xlfn.CEILING.MATH(M25/12) -> 4 | S25: come back make a new table with player, position, probability, and adp so we can sort with it | W25: Brenton Doyle
A26: Corey Seager | B26: Same | C26: =VLOOKUP(A26,$K$1:$L$102,2,FALSE) -> 0.75745606 | E26: Tucker, Kyle | F26: 0.3784005 | I26: {=_xlfn.TEXTSPLIT(E26,",")} -> Tucker | J26: Kyle | K26: =REPLACE(_xlfn.CONCAT(J26," ",I26), 1, 1,"") -> Kyle Tucker | L26: 0.3784005 | M26: =VLOOKUP(K26,ADP!$B$1:$N$646,4,FALSE) -> 8.3 | N26: =_xlfn.CEILING.MATH(M26/12) -> 1 | S26: goal will be to optimize for great season and adp | W26: Luis Robert Jr.
A27: Francisco Lindor | B27: Same | C27: =VLOOKUP(A27,$K$1:$L$102,2,FALSE) -> 0.2826277 | E27: Chourio, Jackson | F27: 0.37210742 | I27: {=_xlfn.TEXTSPLIT(E27,",")} -> Chourio | J27: Jackson | K27: =REPLACE(_xlfn.CONCAT(J27," ",I27), 1, 1,"") -> Jackson Chourio | L27: 0.37210742 | M27: =VLOOKUP(K27,ADP!$B$1:$N$646,4,FALSE) -> 16.6 | N27: =_xlfn.CEILING.MATH(M27/12) -> 2 | W27: Brent Rooker Jr.
A28: Jackson Merrill | B28: Same | C28: =VLOOKUP(A28,$K$1:$L$102,2,FALSE) -> 0.60806304 | E28: Wallner, Matt | F28: 0.36942366 | I28: {=_xlfn.TEXTSPLIT(E28,",")} -> Wallner | J28: Matt | K28: =REPLACE(_xlfn.CONCAT(J28," ",I28), 1, 1,"") -> Matt Wallner | L28: 0.36942366 | M28: =VLOOKUP(K28,ADP!$B$1:$N$646,4,FALSE) -> 270.7 | N28: =_xlfn.CEILING.MATH(M28/12) -> 23 | W28: Daulton Varsho
A29: Joc Perderson | B29: Regress | C29: =VLOOKUP(A29,$K$1:$L$102,2,FALSE) -> #N/A | E29: Rodríguez, Julio | F29: 0.34996724 | I29: {=_xlfn.TEXTSPLIT(E29,",")} -> Rodríguez | J29: Julio | K29: =REPLACE(_xlfn.CONCAT(J29," ",I29), 1, 1,"") -> Julio Rodríguez | L29: 0.34996724 | M29: =VLOOKUP(K29,ADP!$B$1:$N$646,4,FALSE) -> 13.7 | N29: =_xlfn.CEILING.MATH(M29/12) -> 2 | W29: Michael Conforto
A30: Jose Ramirez | B30: Improve | C30: =VLOOKUP(A30,$K$1:$L$102,2,FALSE) -> #N/A | E30: Taveras, Leody | F30: 0.34912145 | I30: {=_xlfn.TEXTSPLIT(E30,",")} -> Taveras | J30: Leody | K30: =REPLACE(_xlfn.CONCAT(J30," ",I30), 1, 1,"") -> Leody Taveras | L30: 0.34912145 | M30: =VLOOKUP(K30,ADP!$B$1:$N$646,4,FALSE) -> 452 | N30: =_xlfn.CEILING.MATH(M30/12) -> 38 | W30: Lane Thomas
A31: Julio Rodriguez | B31: Sane | C31: =VLOOKUP(A31,$K$1:$L$102,2,FALSE) -> #N/A | E31: Lowe, Brandon | F31: 0.33452216 | I31: {=_xlfn.TEXTSPLIT(E31,",")} -> Lowe | J31: Brandon | K31: =REPLACE(_xlfn.CONCAT(J31," ",I31), 1, 1,"") -> Brandon Lowe | L31: 0.33452216 | M31: =VLOOKUP(K31,ADP!$B$1:$N$646,4,FALSE) -> 232.8 | N31: =_xlfn.CEILING.MATH(M31/12) -> 20 | W31: Jo Adell
A32: Kerry Carpenter | B32: Same | C32: =VLOOKUP(A32,$K$1:$L$102,2,FALSE) -> #N/A | E32: Sánchez, Jesús | F32: 0.32095596 | I32: {=_xlfn.TEXTSPLIT(E32,",")} -> Sánchez | J32: Jesús | K32: =REPLACE(_xlfn.CONCAT(J32," ",I32), 1, 1,"") -> Jesús Sánchez | L32: 0.32095596 | M32: =VLOOKUP(K32,ADP!$B$1:$N$646,4,FALSE) -> 233.9 | N32: =_xlfn.CEILING.MATH(M32/12) -> 20 | W32: Trevor Larnach
A33: Ketel Marte | B33: Same | C33: =VLOOKUP(A33,$K$1:$L$102,2,FALSE) -> 0.47614032 | E33: Semien, Marcus | F33: 0.31668463 | I33: {=_xlfn.TEXTSPLIT(E33,",")} -> Semien | J33: Marcus | K33: =REPLACE(_xlfn.CONCAT(J33," ",I33), 1, 1,"") -> Marcus Semien | L33: 0.31668463 | M33: =VLOOKUP(K33,ADP!$B$1:$N$646,4,FALSE) -> 101.1 | N33: =_xlfn.CEILING.MATH(M33/12) -> 9 | W33: Corbin Carroll
A34: Marcell Ozuna | B34: Regress | C34: =VLOOKUP(A34,$K$1:$L$102,2,FALSE) -> 0.29585364 | E34: Perez, Salvador | F34: 0.31409046 | I34: {=_xlfn.TEXTSPLIT(E34,",")} -> Perez | J34: Salvador | K34: =REPLACE(_xlfn.CONCAT(J34," ",I34), 1, 1,"") -> Salvador Perez | L34: 0.31409046 | M34: =VLOOKUP(K34,ADP!$B$1:$N$646,4,FALSE) -> 74.3 | N34: =_xlfn.CEILING.MATH(M34/12) -> 7 | W34: Heliot Ramos
A35: Tyler Fitzgerald | B35: Regress | C35: =VLOOKUP(A35,$K$1:$L$102,2,FALSE) -> #N/A | E35: Machado, Manny | F35: 0.2995941 | I35: {=_xlfn.TEXTSPLIT(E35,",")} -> Machado | J35: Manny | K35: =REPLACE(_xlfn.CONCAT(J35," ",I35), 1, 1,"") -> Manny Machado | L35: 0.2995941 | M35: =VLOOKUP(K35,ADP!$B$1:$N$646,4,FALSE) -> 38.3 | N35: =_xlfn.CEILING.MATH(M35/12) -> 4 | W35: Parker Meadows
A36: Vladimir Guerrero Jr. | B36: Regress | C36: =VLOOKUP(A36,$K$1:$L$102,2,FALSE) -> 0.9117822 | E36: Cruz, Oneil | F36: 0.29848033 | I36: {=_xlfn.TEXTSPLIT(E36,",")} -> Cruz | J36: Oneil | K36: =REPLACE(_xlfn.CONCAT(J36," ",I36), 1, 1,"") -> Oneil Cruz | L36: 0.29848033 | M36: =VLOOKUP(K36,ADP!$B$1:$N$646,4,FALSE) -> 42.5 | N36: =_xlfn.CEILING.MATH(M36/12) -> 4 | W36: Dylan Crews
A37: Xavier Edwards | B37: Same | C37: =VLOOKUP(A37,$K$1:$L$102,2,FALSE) -> #N/A | E37: Ozuna, Marcell | F37: 0.29585364 | I37: {=_xlfn.TEXTSPLIT(E37,",")} -> Ozuna | J37: Marcell | K37: =REPLACE(_xlfn.CONCAT(J37," ",I37), 1, 1,"") -> Marcell Ozuna | L37: 0.29585364 | M37: =VLOOKUP(K37,ADP!$B$1:$N$646,4,FALSE) -> 71.5 | N37: =_xlfn.CEILING.MATH(M37/12) -> 6
A38: Yandy Diaz | B38: Improve | C38: =VLOOKUP(A38,$K$1:$L$102,2,FALSE) -> #N/A | E38: Wood, James | F38: 0.29177788 | I38: {=_xlfn.TEXTSPLIT(E38,",")} -> Wood | J38: James | K38: =REPLACE(_xlfn.CONCAT(J38," ",I38), 1, 1,"") -> James Wood | L38: 0.29177788 | M38: =VLOOKUP(K38,ADP!$B$1:$N$646,4,FALSE) -> 56.4 | N38: =_xlfn.CEILING.MATH(M38/12) -> 5
E39: Caminero, Junior | F39: 0.29131645 | I39: {=_xlfn.TEXTSPLIT(E39,",")} -> Caminero | J39: Junior | K39: =REPLACE(_xlfn.CONCAT(J39," ",I39), 1, 1,"") -> Junior Caminero | L39: 0.29131645 | M39: =VLOOKUP(K39,ADP!$B$1:$N$646,4,FALSE) -> #N/A | N39: =_xlfn.CEILING.MATH(M39/12) -> #N/A
E40: Sosa, Edmundo | F40: 0.28288072 | I40: {=_xlfn.TEXTSPLIT(E40,",")} -> Sosa | J40: Edmundo | K40: =REPLACE(_xlfn.CONCAT(J40," ",I40), 1, 1,"") -> Edmundo Sosa | L40: 0.28288072 | M40: =VLOOKUP(K40,ADP!$B$1:$N$646,4,FALSE) -> 519.8 | N40: =_xlfn.CEILING.MATH(M40/12) -> 44
...

Sheet Pitcher_Tiers
A1: last_name, first_name | B1: Sum(great_season_probability) | J1: Name | K1: Sum(great_season_probability) | L1: ADP | M1: Round
A2: Skenes, Paul | B2: 0.834039 | C2: {=_xlfn.TEXTSPLIT(A2,",")} -> Skenes | D2: Paul | E2: =REPLACE(_xlfn.CONCAT(D2," ",C2), 1, 1,"") -> Paul Skenes | G2: =VLOOKUP(E2,ADP!$B$1:$N$181,4,FALSE) -> 11.3 | J2: Paul Skenes | K2: 0.834039 | L2: 11.3 | M2: =_xlfn.CEILING.MATH(L2/12) -> 1
A3: Crochet, Garrett | B3: 0.8066467 | C3: {=_xlfn.TEXTSPLIT(A3,",")} -> Crochet | D3: Garrett | E3: =REPLACE(_xlfn.CONCAT(D3," ",C3), 1, 1,"") -> Garrett Crochet | G3: =VLOOKUP(E3,ADP!$B$1:$N$181,4,FALSE) -> 24.8 | J3: Garrett Crochet | K3: 0.8066467 | L3: 24.8 | M3: =_xlfn.CEILING.MATH(L3/12) -> 3
A4: Kirby, George | B4: 0.7353988 | C4: {=_xlfn.TEXTSPLIT(A4,",")} -> Kirby | D4: George | E4: =REPLACE(_xlfn.CONCAT(D4," ",C4), 1, 1,"") -> George Kirby | G4: =VLOOKUP(E4,ADP!$B$1:$N$181,4,FALSE) -> 45.8 | J4: George Kirby | K4: 0.7353988 | L4: 45.8 | M4: =_xlfn.CEILING.MATH(L4/12) -> 4
A5: Sánchez, Cristopher | B5: 0.7336966 | C5: {=_xlfn.TEXTSPLIT(A5,",")} -> Sánchez | D5: Cristopher | E5: =REPLACE(_xlfn.CONCAT(D5," ",C5), 1, 1,"") -> Cristopher Sánchez | G5: =VLOOKUP(E5,ADP!$B$1:$N$181,4,FALSE) -> 172.8 | J5: Cristopher Sánchez | K5: 0.7336966 | L5: 172.8 | M5: =_xlfn.CEILING.MATH(L5/12) -> 15
A6: Gilbert, Logan | B6: 0.6581922 | C6: {=_xlfn.TEXTSPLIT(A6,",")} -> Gilbert | D6: Logan | E6: =REPLACE(_xlfn.CONCAT(D6," ",C6), 1, 1,"") -> Logan Gilbert | G6: =VLOOKUP(E6,ADP!$B$1:$N$181,4,FALSE) -> 26 | J6: Logan Gilbert | K6: 0.6581922 | L6: 26 | M6: =_xlfn.CEILING.MATH(L6/12) -> 3
A7: Skubal, Tarik | B7: 0.6535916 | C7: {=_xlfn.TEXTSPLIT(A7,",")} -> Skubal | D7: Tarik | E7: =REPLACE(_xlfn.CONCAT(D7," ",C7), 1, 1,"") -> Tarik Skubal | G7: =VLOOKUP(E7,ADP!$B$1:$N$181,4,FALSE) -> 13.8 | J7: Tarik Skubal | K7: 0.6535916 | L7: 13.8 | M7: =_xlfn.CEILING.MATH(L7/12) -> 2
A8: Steele, Justin | B8: 0.6528158 | C8: {=_xlfn.TEXTSPLIT(A8,",")} -> Steele | D8: Justin | E8: =REPLACE(_xlfn.CONCAT(D8," ",C8), 1, 1,"") -> Justin Steele | G8: =VLOOKUP(E8,ADP!$B$1:$N$181,4,FALSE) -> 121 | J8: Justin Steele | K8: 0.6528158 | L8: 121 | M8: =_xlfn.CEILING.MATH(L8/12) -> 11
A9: Martinez, Nick | B9: 0.62830323 | C9: {=_xlfn.TEXTSPLIT(A9,",")} -> Martinez | D9: Nick | E9: =REPLACE(_xlfn.CONCAT(D9," ",C9), 1, 1,"") -> Nick Martinez | G9: =VLOOKUP(E9,ADP!$B$1:$N$181,4,FALSE) -> 337 | J9: Nick Martinez | K9: 0.62830323 | L9: 337 | M9: =_xlfn.CEILING.MATH(L9/12) -> 29
A10: Greene, Hunter | B10: 0.60481995 | C10: {=_xlfn.TEXTSPLIT(A10,",")} -> Greene | D10: Hunter | E10: =REPLACE(_xlfn.CONCAT(D10," ",C10), 1, 1,"") -> Hunter Greene | G10: =VLOOKUP(E10,ADP!$B$1:$N$181,4,FALSE) -> 95.8 | J10: Hunter Greene | K10: 0.60481995 | L10: 95.8 | M10: =_xlfn.CEILING.MATH(L10/12) -> 8
A11: Cease, Dylan | B11: 0.5722887 | C11: {=_xlfn.TEXTSPLIT(A11,",")} -> Cease | D11: Dylan | E11: =REPLACE(_xlfn.CONCAT(D11," ",C11), 1, 1,"") -> Dylan Cease | G11: =VLOOKUP(E11,ADP!$B$1:$N$181,4,FALSE) -> 46.3 | J11: Dylan Cease | K11: 0.5722887 | L11: 46.3 | M11: =_xlfn.CEILING.MATH(L11/12) -> 4
A12: Fried, Max | B12: 0.5298607 | C12: {=_xlfn.TEXTSPLIT(A12,",")} -> Fried | D12: Max | E12: =REPLACE(_xlfn.CONCAT(D12," ",C12), 1, 1,"") -> Max Fried | G12: =VLOOKUP(E12,ADP!$B$1:$N$181,4,FALSE) -> 99.4 | J12: Max Fried | K12: 0.5298607 | L12: 99.4 | M12: =_xlfn.CEILING.MATH(L12/12) -> 9
A13: López, Reynaldo | B13: 0.52285117 | C13: {=_xlfn.TEXTSPLIT(A13,",")} -> López | D13: Reynaldo | E13: =REPLACE(_xlfn.CONCAT(D13," ",C13), 1, 1,"") -> Reynaldo López | G13: =VLOOKUP(E13,ADP!$B$1:$N$181,4,FALSE) -> 165.5 | J13: Reynaldo López | K13: 0.52285117 | L13: 165.5 | M13: =_xlfn.CEILING.MATH(L13/12) -> 14
A14: Jones, Jared | B14: 0.47025585 | C14: {=_xlfn.TEXTSPLIT(A14,",")} -> Jones | D14: Jared | E14: =REPLACE(_xlfn.CONCAT(D14," ",C14), 1, 1,"") -> Jared Jones | G14: =VLOOKUP(E14,ADP!$B$1:$N$181,4,FALSE) -> #N/A | J14: Jared Jones | K14: 0.47025585 | L14: #N/A | M14: =_xlfn.CEILING.MATH(L14/12) -> #N/A
A15: Anderson, Tyler | B15: 0.44297388 | C15: {=_xlfn.TEXTSPLIT(A15,",")} -> Anderson | D15: Tyler | E15: =REPLACE(_xlfn.CONCAT(D15," ",C15), 1, 1,"") -> Tyler Anderson | G15: =VLOOKUP(E15,ADP!$B$1:$N$181,4,FALSE) -> #N/A | J15: Tyler Anderson | K15: 0.44297388 | L15: #N/A | M15: =_xlfn.CEILING.MATH(L15/12) -> #N/A
A16: Ragans, Cole | B16: 0.42130622 | C16: {=_xlfn.TEXTSPLIT(A16,",")} -> Ragans | D16: Cole | E16: =REPLACE(_xlfn.CONCAT(D16," ",C16), 1, 1,"") -> Cole Ragans | G16: =VLOOKUP(E16,ADP!$B$1:$N$181,4,FALSE) -> 49.5 | J16: Cole Ragans | K16: 0.42130622 | L16: 49.5 | M16: =_xlfn.CEILING.MATH(L16/12) -> 5
A17: Blanco, Ronel | B17: 0.40907443 | C17: {=_xlfn.TEXTSPLIT(A17,",")} -> Blanco | D17: Ronel | E17: =REPLACE(_xlfn.CONCAT(D17," ",C17), 1, 1,"") -> Ronel Blanco | G17: =VLOOKUP(E17,ADP!$B$1:$N$181,4,FALSE) -> 246.3 | J17: Ronel Blanco | K17: 0.40907443 | L17: 246.3 | M17: =_xlfn.CEILING.MATH(L17/12) -> 21
A18: Gray, Sonny | B18: 0.38718066 | C18: {=_xlfn.TEXTSPLIT(A18,",")} -> Gray | D18: Sonny | E18: =REPLACE(_xlfn.CONCAT(D18," ",C18), 1, 1,"") -> Sonny Gray | G18: =VLOOKUP(E18,ADP!$B$1:$N$181,4,FALSE) -> 109.9 | J18: Sonny Gray | K18: 0.38718066 | L18: 109.9 | M18: =_xlfn.CEILING.MATH(L18/12) -> 10
A19: Eovaldi, Nathan | B19: 0.3723135 | C19: {=_xlfn.TEXTSPLIT(A19,",")} -> Eovaldi | D19: Nathan | E19: =REPLACE(_xlfn.CONCAT(D19," ",C19), 1, 1,"") -> Nathan Eovaldi | G19: =VLOOKUP(E19,ADP!$B$1:$N$181,4,FALSE) -> 200.4 | J19: Nathan Eovaldi | K19: 0.3723135 | L19: 200.4 | M19: =_xlfn.CEILING.MATH(L19/12) -> 17
A20: Burnes, Corbin | B20: 0.3411315 | C20: {=_xlfn.TEXTSPLIT(A20,",")} -> Burnes | D20: Corbin | E20: =REPLACE(_xlfn.CONCAT(D20," ",C20), 1, 1,"") -> Corbin Burnes | G20: =VLOOKUP(E20,ADP!$B$1:$N$181,4,FALSE) -> 38.9 | J20: Corbin Burnes | K20: 0.3411315 | L20: 38.9 | M20: =_xlfn.CEILING.MATH(L20/12) -> 4
A21: Brown, Hunter | B21: 0.33580303 | C21: {=_xlfn.TEXTSPLIT(A21,",")} -> Brown | D21: Hunter | E21: =REPLACE(_xlfn.CONCAT(D21," ",C21), 1, 1,"") -> Hunter Brown | G21: =VLOOKUP(E21,ADP!$B$1:$N$181,4,FALSE) -> 98 | J21: Hunter Brown | K21: 0.33580303 | L21: 98 | M21: =_xlfn.CEILING.MATH(L21/12) -> 9
A22: Valdez, Framber | B22: 0.30962187 | C22: {=_xlfn.TEXTSPLIT(A22,",")} -> Valdez | D22: Framber | E22: =REPLACE(_xlfn.CONCAT(D22," ",C22), 1, 1,"") -> Framber Valdez | G22: =VLOOKUP(E22,ADP!$B$1:$N$181,4,FALSE) -> 61.3 | J22: Framber Valdez | K22: 0.30962187 | L22: 61.3 | M22: =_xlfn.CEILING.MATH(L22/12) -> 6
A23: Bradley, Taj | B23: 0.30158094 | C23: {=_xlfn.TEXTSPLIT(A23,",")} -> Bradley | D23: Taj | E23: =REPLACE(_xlfn.CONCAT(D23," ",C23), 1, 1,"") -> Taj Bradley | G23: =VLOOKUP(E23,ADP!$B$1:$N$181,4,FALSE) -> #N/A | J23: Taj Bradley | K23: 0.30158094 | L23: #N/A | M23: =_xlfn.CEILING.MATH(L23/12) -> #N/A
A24: Wheeler, Zack | B24: 0.28649575 | C24: {=_xlfn.TEXTSPLIT(A24,",")} -> Wheeler | D24: Zack | E24: =REPLACE(_xlfn.CONCAT(D24," ",C24), 1, 1,"") -> Zack Wheeler | G24: =VLOOKUP(E24,ADP!$B$1:$N$181,4,FALSE) -> 21.1 | J24: Zack Wheeler | K24: 0.28649575 | L24: 21.1 | M24: =_xlfn.CEILING.MATH(L24/12) -> 2
A25: Pfaadt, Brandon | B25: 0.28205168 | C25: {=_xlfn.TEXTSPLIT(A25,",")} -> Pfaadt | D25: Brandon | E25: =REPLACE(_xlfn.CONCAT(D25," ",C25), 1, 1,"") -> Brandon Pfaadt | G25: =VLOOKUP(E25,ADP!$B$1:$N$181,4,FALSE) -> #N/A | J25: Brandon Pfaadt | K25: 0.28205168 | L25: #N/A | M25: =_xlfn.CEILING.MATH(L25/12) -> #N/A
A26: Stone, Gavin | B26: 0.27405342 | C26: {=_xlfn.TEXTSPLIT(A26,",")} -> Stone | D26: Gavin | E26: =REPLACE(_xlfn.CONCAT(D26," ",C26), 1, 1,"") -> Gavin Stone | G26: =VLOOKUP(E26,ADP!$B$1:$N$181,4,FALSE) -> #N/A | J26: Gavin Stone | K26: 0.27405342 | L26: #N/A | M26: =_xlfn.CEILING.MATH(L26/12) -> #N/A
A27: Ryan, Joe | B27: 0.2700745 | C27: {=_xlfn.TEXTSPLIT(A27,",")} -> Ryan | D27: Joe | E27: =REPLACE(_xlfn.CONCAT(D27," ",C27), 1, 1,"") -> Joe Ryan | G27: =VLOOKUP(E27,ADP!$B$1:$N$181,4,FALSE) -> 92.2 | J27: Joe Ryan | K27: 0.2700745 | L27: 92.2 | M27: =_xlfn.CEILING.MATH(L27/12) -> 8
A28: Montgomery, Jordan | B28: 0.25958872 | C28: {=_xlfn.TEXTSPLIT(A28,",")} -> Montgomery | D28: Jordan | E28: =REPLACE(_xlfn.CONCAT(D28," ",C28), 1, 1,"") -> Jordan Montgomery | G28: =VLOOKUP(E28,ADP!$B$1:$N$181,4,FALSE) -> #N/A | J28: Jordan Montgomery | K28: 0.25958872 | L28: #N/A | M28: =_xlfn.CEILING.MATH(L28/12) -> #N/A
A29: Imanaga, Shota | B29: 0.252659 | C29: {=_xlfn.TEXTSPLIT(A29,",")} -> Imanaga | D29: Shota | E29: =REPLACE(_xlfn.CONCAT(D29," ",C29), 1, 1,"") -> Shota Imanaga | G29: =VLOOKUP(E29,ADP!$B$1:$N$181,4,FALSE) -> 77.3 | J29: Shota Imanaga | K29: 0.252659 | L29: 77.3 | M29: =_xlfn.CEILING.MATH(L29/12) -> 7
A30: Castillo, Luis | B30: 0.22768252 | C30: {=_xlfn.TEXTSPLIT(A30,",")} -> Castillo | D30: Luis | E30: =REPLACE(_xlfn.CONCAT(D30," ",C30), 1, 1,"") -> Luis Castillo | G30: =VLOOKUP(E30,ADP!$B$1:$N$181,4,FALSE) -> 95.3 | J30: Luis Castillo | K30: 0.22768252 | L30: 95.3 | M30: =_xlfn.CEILING.MATH(L30/12) -> 8
A31: Pepiot, Ryan | B31: 0.22512558 | C31: {=_xlfn.TEXTSPLIT(A31,",")} -> Pepiot | D31: Ryan | E31: =REPLACE(_xlfn.CONCAT(D31," ",C31), 1, 1,"") -> Ryan Pepiot | G31: =VLOOKUP(E31,ADP!$B$1:$N$181,4,FALSE) -> 166.3 | J31: Ryan Pepiot | K31: 0.22512558 | L31: 166.3 | M31: =_xlfn.CEILING.MATH(L31/12) -> 14
A32: Rodón, Carlos | B32: 0.22314149 | C32: {=_xlfn.TEXTSPLIT(A32,",")} -> Rodón | D32: Carlos | E32: =REPLACE(_xlfn.CONCAT(D32," ",C32), 1, 1,"") -> Carlos Rodón | G32: =VLOOKUP(E32,ADP!$B$1:$N$181,4,FALSE) -> 129.2 | J32: Carlos Rodón | K32: 0.22314149 | L32: 129.2 | M32: =_xlfn.CEILING.MATH(L32/12) -> 11
A33: Glasnow, Tyler | B33: 0.2144415 | C33: {=_xlfn.TEXTSPLIT(A33,",")} -> Glasnow | D33: Tyler | E33: =REPLACE(_xlfn.CONCAT(D33," ",C33), 1, 1,"") -> Tyler Glasnow | G33: =VLOOKUP(E33,ADP!$B$1:$N$181,4,FALSE) -> 98.4 | J33: Tyler Glasnow | K33: 0.2144415 | L33: 98.4 | M33: =_xlfn.CEILING.MATH(L33/12) -> 9
A34: Sale, Chris | B34: 0.21010177 | C34: {=_xlfn.TEXTSPLIT(A34,",")} -> Sale | D34: Chris | E34: =REPLACE(_xlfn.CONCAT(D34," ",C34), 1, 1,"") -> Chris Sale | G34: =VLOOKUP(E34,ADP!$B$1:$N$181,4,FALSE) -> 37.3 | J34: Chris Sale | K34: 0.21010177 | L34: 37.3 | M34: =_xlfn.CEILING.MATH(L34/12) -> 4
A35: Suárez, Ranger | B35: 0.20669363 | C35: {=_xlfn.TEXTSPLIT(A35,",")} -> Suárez | D35: Ranger | E35: =REPLACE(_xlfn.CONCAT(D35," ",C35), 1, 1,"") -> Ranger Suárez | G35: =VLOOKUP(E35,ADP!$B$1:$N$181,4,FALSE) -> 263.3 | J35: Ranger Suárez | K35: 0.20669363 | L35: 263.3 | M35: =_xlfn.CEILING.MATH(L35/12) -> 22
A36: Wacha, Michael | B36: 0.19448388 | C36: {=_xlfn.TEXTSPLIT(A36,",")} -> Wacha | D36: Michael | E36: =REPLACE(_xlfn.CONCAT(D36," ",C36), 1, 1,"") -> Michael Wacha | G36: =VLOOKUP(E36,ADP!$B$1:$N$181,4,FALSE) -> 279.7 | J36: Michael Wacha | K36: 0.19448388 | L36: 279.7 | M36: =_xlfn.CEILING.MATH(L36/12) -> 24
A37: Kikuchi, Yusei | B37: 0.19081157 | C37: {=_xlfn.TEXTSPLIT(A37,",")} -> Kikuchi | D37: Yusei | E37: =REPLACE(_xlfn.CONCAT(D37," ",C37), 1, 1,"") -> Yusei Kikuchi | G37: =VLOOKUP(E37,ADP!$B$1:$N$181,4,FALSE) -> #N/A | J37: Yusei Kikuchi | K37: 0.19081157 | L37: #N/A | M37: =_xlfn.CEILING.MATH(L37/12) -> #N/A
A38: Bibee, Tanner | B38: 0.17540014 | C38: {=_xlfn.TEXTSPLIT(A38,",")} -> Bibee | D38: Tanner | E38: =REPLACE(_xlfn.CONCAT(D38," ",C38), 1, 1,"") -> Tanner Bibee | G38: =VLOOKUP(E38,ADP!$B$1:$N$181,4,FALSE) -> 88.7 | J38: Tanner Bibee | K38: 0.17540014 | L38: 88.7 | M38: =_xlfn.CEILING.MATH(L38/12) -> 8
A39: Gore, MacKenzie | B39: 0.16272049 | C39: {=_xlfn.TEXTSPLIT(A39,",")} -> Gore | D39: MacKenzie | E39: =REPLACE(_xlfn.CONCAT(D39," ",C39), 1, 1,"") -> MacKenzie Gore | G39: =VLOOKUP(E39,ADP!$B$1:$N$181,4,FALSE) -> #N/A | J39: MacKenzie Gore | K39: 0.16272049 | L39: #N/A | M39: =_xlfn.CEILING.MATH(L39/12) -> #N/A
A40: Bello, Brayan | B40: 0.15414311 | C40: {=_xlfn.TEXTSPLIT(A40,",")} -> Bello | D40: Brayan | E40: =REPLACE(_xlfn.CONCAT(D40," ",C40), 1, 1,"") -> Brayan Bello | G40: =VLOOKUP(E40,ADP!$B$1:$N$181,4,FALSE) -> #N/A | J40: Brayan Bello | K40: 0.15414311 | L40: #N/A | M40: =_xlfn.CEILING.MATH(L40/12) -> #N/A
...

Sheet ADP
A1: # | B1: Name | C1: Team | D1: POS | E1: ADP | F1: Roster% | G1: Start% | H1: PA | I1: IP | J1: Dollars | K1: Card | L1: SB | M1: HR | N1: Dollars | O1: Card
A2: 1 | B2: Shohei Ohtani | C2: LAD | D2: DH | E2: 1.5 | F2: 1 | G2: 1 | H2: 731 | J2: 62.4 | L2: 59 | M2: 54 | N2: 62.4
A3: 2 | B3: Aaron Judge | C3: NYY | D3: OF/DH | E3: 3.4 | F3: 1 | G3: 1 | H3: 704 | J3: 53.6 | L3: 31 | M3: 32 | N3: 46.3
A4: 3 | B4: Bobby Witt Jr. | C4: KCR | D4: SS | E4: 1.6 | F4: 1 | G4: 1 | H4: 709 | J4: 46.3 | L4: 10 | M4: 58 | N4: 53.6
A5: 4 | B5: José Ramírez | C5: CLE | D5: 3B/DH | E5: 5 | F5: 1 | G5: 1 | H5: 682 | J5: 43.3 | L5: 67 | M5: 25 | N5: 32.7
A6: 5 | B6: Juan Soto | C6: NYM | D6: OF | E6: 7.8 | F6: 1 | G6: 1 | H6: 713 | J6: 37.3 | L6: 41 | M6: 39 | N6: 43.3
A7: 6 | B7: Tarik Skubal | C7: DET | D7: SP | E7: 13.8 | F7: 1 | G7: 1 | I7: 192 | J7: 37.2 | L7: 21 | M7: 37 | N7: 33.4
A8: 7 | B8: Gunnar Henderson | C8: BAL | D8: SS | E8: 6.1 | F8: 1 | G8: 0.99 | H8: 719 | J8: 33.4 | L8: 7 | M8: 41 | N8: 37.3
A9: 8 | B9: Zack Wheeler | C9: PHI | D9: SP | E9: 21.1 | F9: 1 | G9: 1 | I9: 200 | J9: 33 | L9: 11 | M9: 23 | N9: 7.8
A10: 9 | B10: Elly De La Cruz | C10: CIN | D10: SS | E10: 4.5 | F10: 1 | G10: 1 | H10: 696 | J10: 32.7 | L10: 35 | M10: 22 | N10: 22.5
A11: 10 | B11: Chris Sale | C11: ATL | D11: SP | E11: 37.3 | F11: 1 | G11: 1 | I11: 177.1 | J11: 32.7 | L11: 11 | M11: 21 | N11: 8.1
A12: 11 | B12: Francisco Lindor | C12: NYM | D12: SS | E12: 15.2 | F12: 1 | G12: 1 | H12: 689 | J12: 30.8 | L12: 16 | M12: 19 | N12: 15.4
A13: 12 | B13: William Contreras | C13: MIL | D13: C/DH | E13: 24.1 | F13: 1 | G13: 1 | H13: 679 | J13: 30.2 | L13: 24 | M13: 20 | N13: 16.5
A14: 13 | B14: Vladimir Guerrero Jr. | C14: TOR | D14: 1B/DH | E14: 14.4 | F14: 1 | G14: 1 | H14: 697 | J14: 30.2 | L14: 2 | M14: 30 | N14: 30.2
A15: 14 | B15: Marcell Ozuna | C15: ATL | D15: DH | E15: 71.5 | F15: 1 | G15: 1 | H15: 688 | J15: 29.6 | L15: 29 | M15: 33 | N15: 30.8
A16: 15 | B16: Brent Rooker | C16: ATH | D16: DH | E16: 67.4 | F16: 1 | G16: 0.99 | H16: 614 | J16: 29.3 | L16: 22 | M16: 21 | N16: 18.9
A17: 16 | B17: Jarren Duran | C17: BOS | D17: OF | E17: 21.1 | F17: 1 | G17: 1 | H17: 735 | J17: 28.8 | L17: 6 | M17: 35 | N17: 27
A18: 17 | B18: Yordan Alvarez | C18: HOU | D18: OF/DH | E18: 17.6 | F18: 1 | G18: 1 | H18: 635 | J18: 27 | L18: 34 | M18: 21 | N18: 28.8
A19: 18 | B19: Ketel Marte | C19: ARI | D19: 2B/DH | E19: 32.4 | F19: 1 | G19: 1 | H19: 583 | J19: 26.4 | L19: 7 | M19: 30 | N19: 20.4
A20: 19 | B20: Willy Adames | C20: SFG | D20: SS | E20: 94 | F20: 1 | G20: 0.99 | H20: 688 | J20: 25.8 | L20: 40 | M20: 24 | N20: 20
A21: 20 | B21: Paul Skenes | C21: PIT | D21: SP | E21: 11.3 | F21: 1 | G21: 1 | I21: 133 | J21: 24.9 | L21: 9 | M21: 23 | N21: 30.2
A22: 21 | B22: Kyle Schwarber | C22: PHI | D22: DH | E22: 77.7 | F22: 1 | G22: 0.97 | H22: 692 | J22: 24.5 | L22: 16 | M22: 24 | N22: 22.3
A23: 22 | B23: Teoscar Hernández | C23: LAD | D23: OF | E23: 61 | F23: 1 | G23: 1 | H23: 652 | J23: 24.3 | L23: 9 | M23: 22 | N23: 17.2
A24: 23 | B24: Logan Gilbert | C24: SEA | D24: SP | E24: 26 | F24: 1 | G24: 1 | I24: 208.1 | J24: 24.1 | L24: 19 | M24: 21 | N24: 18.2
A25: 24 | B25: Salvador Perez | C25: KCR | D25: C/1B/DH | E25: 74.3 | F25: 1 | G25: 1 | H25: 652 | J25: 22.9 | L25: 0 | M25: 19 | N25: 3.2
A26: 25 | B26: Shota Imanaga | C26: CHC | D26: SP | E26: 77.3 | F26: 1 | G26: 1 | I26: 173 | J26: 22.7 | L26: 7 | M26: 36 | N26: 26.4
A27: 26 | B27: Manny Machado | C27: SDP | D27: 3B/DH | E27: 38.3 | F27: 1 | G27: 1 | H27: 643 | J27: 22.7 | L27: 16 | M27: 4 | N27: -8.9
A28: 27 | B28: Corbin Carroll | C28: ARI | D28: OF | E28: 9.2 | F28: 1 | G28: 1 | H28: 684 | J28: 22.5 | L28: 3 | M28: 28 | N28: 17.7
A29: 28 | B29: Emmanuel Clase | C29: CLE | D29: RP | E29: 34.9 | F29: 1 | G29: 1 | I29: 74 | J29: 22.5 | L29: 10 | M29: 16 | N29: 3.6
A30: 29 | B30: Yainer Diaz | C30: HOU | D30: C/DH | E30: 57.6 | F30: 1 | G30: 1 | H30: 619 | J30: 22.3 | L30: 11 | M30: 29 | N30: 22.7
A31: 30 | B31: Jackson Merrill | C31: SDP | D31: OF | E31: 25.6 | F31: 1 | G31: 1 | H31: 593 | J31: 22.3 | L31: 0 | M31: 29 | N31: 13.3
A32: 31 | B32: Anthony Santander | C32: TOR | D32: OF/DH | E32: 102.4 | F32: 1 | G32: 1 | H32: 665 | J32: 21.9 | L32: 22 | M32: 21 | N32: 13.9
A33: 32 | B33: Cal Raleigh | C33: SEA | D33: C | E33: 88.4 | F33: 1 | G33: 1 | H33: 628 | J33: 21.7 | L33: 19 | M33: 16 | N33: 11.5
A34: 33 | B34: Bryce Miller | C34: SEA | D34: SP | E34: 79 | F34: 1 | G34: 1 | I34: 180 | J34: 21.4 | L34: 1 | M34: 30 | N34: 13
A35: 34 | B35: Seth Lugo | C35: KCR | D35: SP | E35: 189 | F35: 1 | G35: 1 | I35: 206.1 | J35: 21.3 | L35: 31 | M35: 20 | N35: 13.6
A36: 35 | B36: Jose Altuve | C36: HOU | D36: 2B | E36: 59.8 | F36: 1 | G36: 1 | H36: 682 | J36: 21.3 | L36: 3 | M36: 34 | N36: 15.4
A37: 36 | B37: Jurickson Profar | C37: ATL | D37: OF | E37: 187 | F37: 1 | G37: 1 | H37: 668 | J37: 21.1 | L37: 14 | M37: 9 | N37: -1.7
A38: 37 | B38: Corbin Burnes | C38: ARI | D38: SP | E38: 38.9 | F38: 1 | G38: 1 | I38: 194 | J38: 20.8 | L38: 2 | M38: 16 | N38: 22.3
A39: 38 | B39: Bryce Harper | C39: PHI | D39: 1B | E39: 22.6 | F39: 1 | G39: 1 | H39: 631 | J39: 20.4 | L39: 22 | M39: 20 | N39: 21.3
A40: 39 | B40: Jazz Chisholm Jr. | C40: NYY | D40: 3B/OF | E40: 23.4 | F40: 1 | G40: 1 | H40: 621 | J40: 20 | L40: 12 | M40: 33 | N40: 24.3
...
